File: Laboratory Exercise 3 Standardized Testing report and discussion/Aluminium_Data.txt
Time  1 - fast sample rate [s]	Extensometer [V]	Force [V]	SG signal [µm/m]	Extensometer_Scaled [mm/mm]	Force_Scaled [N]
0	0.02567	0.05208	-19.14	0.00128	156.25
0.4000	0.02570	0.05206	-19.22	0.00128	156.17
0.8000	0.02568	0.05215	-19.33	0.00128	156.44
1.200	0.02562	0.05210	-19.27	0.00128	156.31
1.600	0.02568	0.05216	-19.43	0.00128	156.48
2.000	0.02565	0.05215	-19.22	0.00128	156.45
2.400	0.02569	0.05218	-19.27	0.00128	156.53
2.800	0.02564	0.05211	-19.27	0.00128	156.34
3.200	0.02563	0.05213	-19.49	0.00128	156.39
3.600	0.02570	0.05209	-19.38	0.00128	156.27
4.000	0.02567	0.05220	-19.57	0.00128	156.60
4.400	0.02557	0.05212	-19.51	0.00128	156.37
4.800	0.02567	0.05217	-19.59	0.00128	156.50
5.200	0.02570	0.05216	-19.54	0.00129	156.47
5.600	0.02567	0.05219	-19.49	0.00128	156.56
6.000	0.02569	0.05213	-19.54	0.00128	156.38
6.400	0.02570	0.05225	-19.51	0.00128	156.74
6.800	0.02566	0.05214	-19.65	0.00128	156.41
7.200	0.02561	0.05222	-19.59	0.00128	156.66
7.600	0.02574	0.05233	-19.67	0.00129	156.98
8.000	0.02580	0.05233	-19.62	0.00129	156.98
8.400	0.02567	0.05219	-19.65	0.00128	156.57
8.800	0.02570	0.05219	-19.46	0.00128	156.58
9.200	0.02570	0.05214	-19.65	0.00128	156.41
9.600	0.02565	0.05222	-19.41	0.00128	156.66
10.00	0.02568	0.05219	-19.46	0.00128	156.57
10.40	0.02571	0.05219	-19.57	0.00129	156.56
10.80	0.02570	0.05217	-19.59	0.00128	156.51
11.20	0.02570	0.05219	-19.57	0.00129	156.58
11.60	0.02575	0.05223	-19.43	0.00129	156.69
12.00	0.02571	0.05224	-19.43	0.00129	156.71
12.40	0.02570	0.05217	-19.51	0.00128	156.50
12.80	0.02566	0.05216	-19.59	0.00128	156.48
13.20	0.02570	0.05219	-19.46	0.00128	156.57
13.60	0.02570	0.05217	-19.59	0.00129	156.50
14.00	0.02571	0.05213	-19.51	0.00129	156.40
14.40	0.02573	0.05218	-19.30	0.00129	156.53
14.80	0.02566	0.05210	-19.27	0.00128	156.29
15.20	0.02566	0.05209	-19.41	0.00128	156.28
15.60	0.02566	0.05209	-19.41	0.00128	156.26
16.00	0.02564	0.05209	-19.43	0.00128	156.28
16.40	0.00198	0.05994	-24.60	0.000099	179.82
16.80	0.00255	0.07723	-35.08	0.00013	231.68
17.20	0.00322	0.09436	-45.32	0.00016	283.09
17.60	0.00387	0.1109	-55.34	0.00019	332.81
18.00	0.00447	0.1264	-64.32	0.00022	379.24
18.40	0.00498	0.1407	-73.02	0.00025	422.18
18.80	0.00543	0.1541	-81.12	0.00027	462.38
19.20	0.00603	0.1671	-88.69	0.00030	501.37
19.60	0.00640	0.1801	-96.53	0.00032	540.18
20.00	0.00698	0.1927	-104.10	0.00035	578.22
20.40	0.00746	0.2051	-111.27	0.00037	615.19
20.80	0.00789	0.2164	-118.25	0.00039	649.17
21.20	0.00823	0.2273	-124.68	0.00041	682.00
21.60	0.00860	0.2382	-130.92	0.00043	714.59
22.00	0.00914	0.2488	-137.29	0.00046	746.54
22.40	0.00946	0.2589	-143.15	0.00047	776.84
22.80	0.00979	0.2685	-149.04	0.00049	805.56
23.20	0.01011	0.2779	-154.43	0.00051	833.68
23.60	0.01042	0.2872	-159.84	0.00052	861.60
24.00	0.01088	0.2962	-165.12	0.00054	888.47
24.40	0.01108	0.3044	-169.92	0.00055	913.19
24.80	0.01141	0.3120	-174.58	0.00057	935.97
25.20	0.01173	0.3190	-179.27	0.00059	957.06
25.60	0.01196	0.3259	-183.56	0.00060	977.78
26.00	0.01229	0.3327	-187.64	0.00061	998.03
26.40	0.01259	0.3373	-190.97	0.00063	1011.9
26.80	0.01284	0.3421	-194.36	0.00064	1026.3
27.20	0.01297	0.3474	-198.28	0.00065	1042.3
27.60	0.01321	0.3524	-201.85	0.00066	1057.3
28.00	0.01356	0.3577	-205.37	0.00068	1073.0
28.40	0.01379	0.3629	-208.78	0.00069	1088.7
28.80	0.01397	0.3682	-212.57	0.00070	1104.7
29.20	0.01416	0.3741	-216.27	0.00071	1122.2
29.60	0.01446	0.3802	-220.00	0.00072	1140.6
30.00	0.01476	0.3862	-223.74	0.00074	1158.5
30.40	0.01486	0.3920	-227.39	0.00074	1176.1
30.80	0.01513	0.3979	-230.96	0.00076	1193.6
31.20	0.01538	0.4042	-234.67	0.00077	1212.5
31.60	0.01569	0.4105	-238.59	0.00078	1231.4
32.00	0.01574	0.4164	-242.26	0.00079	1249.3
32.40	0.01602	0.4222	-245.68	0.00080	1266.5
32.80	0.01633	0.4284	-249.54	0.00082	1285.1
33.20	0.01661	0.4349	-253.33	0.00083	1304.6
33.60	0.01670	0.4412	-257.22	0.00083	1323.5
34.00	0.01695	0.4472	-260.82	0.00085	1341.6
34.40	0.01726	0.4532	-264.55	0.00086	1359.5
34.80	0.01747	0.4594	-268.07	0.00087	1378.3
35.20	0.01763	0.4657	-272.09	0.00088	1397.1
35.60	0.01791	0.4719	-275.91	0.00090	1415.8
36.00	0.01816	0.4778	-279.42	0.00091	1433.4
36.40	0.01831	0.4838	-283.08	0.00092	1451.4
36.80	0.01857	0.4898	-286.78	0.00093	1469.3
37.20	0.01883	0.4961	-290.43	0.00094	1488.3
37.60	0.01917	0.5022	-294.11	0.00096	1506.5
38.00	0.01923	0.5078	-297.50	0.00096	1523.5
38.40	0.01945	0.5139	-301.04	0.00097	1541.7
38.80	0.01976	0.5200	-304.83	0.00099	1560.1
39.20	0.01998	0.5262	-308.59	0.00100	1578.7
39.60	0.02015	0.5321	-312.05	0.00101	1596.2
40.00	0.02038	0.5377	-315.71	0.00102	1613.2
40.40	0.02066	0.5436	-319.12	0.00103	1630.9
40.80	0.02085	0.5497	-322.90	0.00104	1649.0
41.20	0.02106	0.5558	-326.58	0.00105	1667.5
41.60	0.02133	0.5615	-330.21	0.00107	1684.5
42.00	0.02162	0.5674	-333.78	0.00108	1702.3
42.40	0.02177	0.5738	-337.67	0.00109	1721.3
42.80	0.02201	0.5802	-341.48	0.00110	1740.7
43.20	0.02227	0.5865	-345.32	0.00111	1759.5
43.60	0.02253	0.5924	-348.79	0.00113	1777.3
44.00	0.02268	0.5986	-352.65	0.00113	1795.9
44.40	0.02292	0.6051	-356.57	0.00115	1815.2
44.80	0.02319	0.6115	-360.49	0.00116	1834.5
45.20	0.02348	0.6178	-364.30	0.00117	1853.3
45.60	0.02361	0.6237	-367.74	0.00118	1871.0
46.00	0.02383	0.6301	-371.93	0.00119	1890.2
46.40	0.02413	0.6365	-375.61	0.00121	1909.6
46.80	0.02444	0.6432	-379.74	0.00122	1929.6
47.20	0.02476	0.6495	-383.58	0.00124	1948.5
47.60	0.02501	0.6558	-387.44	0.00125	1967.4
48.00	0.02512	0.6626	-391.44	0.00126	1987.7
48.40	0.02538	0.6692	-395.28	0.00127	2007.6
48.80	0.02570	0.6759	-399.44	0.00128	2027.8
49.20	0.02598	0.6822	-403.44	0.00130	2046.7
49.60	0.02619	0.6888	-407.19	0.00131	2066.4
50.00	0.02638	0.6954	-411.25	0.00132	2086.1
50.40	0.02662	0.7022	-415.46	0.00133	2106.7
50.80	0.02694	0.7088	-419.56	0.00135	2126.4
51.20	0.02712	0.7153	-423.51	0.00136	2145.8
51.60	0.02729	0.7221	-427.35	0.00136	2166.4
52.00	0.02756	0.7289	-431.59	0.00138	2186.6
52.40	0.02787	0.7360	-436.22	0.00139	2208.0
52.80	0.02816	0.7428	-440.30	0.00141	2228.3
53.20	0.02848	0.7495	-444.30	0.00142	2248.5
53.60	0.02868	0.7563	-448.27	0.00143	2268.9
54.00	0.02881	0.7635	-452.67	0.00144	2290.5
54.40	0.02912	0.7706	-456.99	0.00146	2311.9
54.80	0.02945	0.7773	-461.15	0.00147	2331.9
55.20	0.02977	0.7844	-465.39	0.00149	2353.1
55.60	0.03006	0.7916	-469.79	0.00150	2374.8
56.00	0.03026	0.7987	-474.16	0.00151	2396.0
56.40	0.03057	0.8058	-478.58	0.00153	2417.5
56.80	0.03086	0.8126	-482.64	0.00154	2437.9
57.20	0.03107	0.8199	-486.95	0.00155	2459.8
57.60	0.03131	0.8273	-491.38	0.00157	2481.8
58.00	0.03162	0.8347	-496.20	0.00158	2504.0
58.40	0.03193	0.8419	-500.79	0.00160	2525.8
58.80	0.03220	0.8491	-504.73	0.00161	2547.3
59.20	0.03247	0.8565	-509.21	0.00162	2569.6
59.60	0.03269	0.8639	-514.04	0.00163	2591.7
60.00	0.03304	0.8716	-518.78	0.00165	2614.9
60.40	0.03325	0.8792	-523.47	0.00166	2637.5
60.80	0.03353	0.8865	-527.85	0.00168	2659.4
61.20	0.03382	0.8939	-532.19	0.00169	2681.7
61.60	0.03412	0.9013	-536.86	0.00171	2704.0
62.00	0.03442	0.9092	-541.73	0.00172	2727.5
62.40	0.03472	0.9167	-546.40	0.00174	2750.2
62.80	0.03500	0.9239	-550.75	0.00175	2771.7
63.20	0.03530	0.9312	-555.28	0.00176	2793.6
63.60	0.03559	0.9389	-560.05	0.00178	2816.7
64.00	0.03588	0.9467	-564.95	0.00179	2840.1
64.40	0.03607	0.9542	-569.51	0.00180	2862.7
64.80	0.03635	0.9616	-574.04	0.00182	2884.8
65.20	0.03663	0.9695	-579.11	0.00183	2908.5
65.60	0.03695	0.9775	-584.01	0.00185	2932.6
66.00	0.03725	0.9855	-589.11	0.00186	2956.5
66.40	0.03763	0.9931	-593.72	0.00188	2979.2
66.80	0.03786	1.001	-598.41	0.00189	3002.0
67.20	0.03819	1.009	-603.45	0.00191	3026.2
67.60	0.03849	1.017	-608.59	0.00192	3050.3
68.00	0.03884	1.025	-613.36	0.00194	3074.5
68.40	0.03910	1.032	-618.19	0.00196	3097.1
68.80	0.03942	1.040	-623.01	0.00197	3121.2
69.20	0.03974	1.048	-628.19	0.00199	3145.2
69.60	0.04005	1.057	-633.22	0.00200	3169.5
70.00	0.04036	1.065	-638.26	0.00202	3194.0
70.40	0.04067	1.072	-643.22	0.00203	3217.5
70.80	0.04098	1.081	-648.10	0.00205	3241.7
71.20	0.04130	1.089	-653.24	0.00206	3265.7
71.60	0.04161	1.097	-658.28	0.00208	3290.2
72.00	0.04191	1.105	-663.56	0.00210	3313.9
72.40	0.04223	1.113	-668.57	0.00211	3338.1
72.80	0.04253	1.121	-673.72	0.00213	3361.7
73.20	0.04285	1.129	-679.26	0.00214	3387.4
73.60	0.04319	1.138	-684.57	0.00216	3412.8
74.00	0.04348	1.146	-690.00	0.00217	3437.9
74.40	0.04384	1.154	-695.20	0.00219	3461.0
74.80	0.04411	1.162	-700.59	0.00221	3484.7
75.20	0.04449	1.170	-706.16	0.00222	3510.2
75.60	0.04496	1.179	-712.13	0.00225	3535.5
76.00	0.04531	1.187	-717.75	0.00227	3559.6
76.40	0.04565	1.194	-723.46	0.00228	3583.1
76.80	0.04596	1.203	-729.51	0.00230	3608.2
77.20	0.04650	1.211	-735.54	0.00233	3633.3
77.60	0.04687	1.219	-741.85	0.00234	3658.1
78.00	0.04720	1.227	-748.28	0.00236	3681.7
78.40	0.04763	1.235	-754.60	0.00238	3706.0
78.80	0.04814	1.243	-761.13	0.00241	3729.9
79.20	0.04845	1.251	-768.03	0.00242	3753.9
79.60	0.04896	1.259	-775.23	0.00245	3777.6
80.00	0.04939	1.267	-782.13	0.00247	3799.7
80.40	0.04996	1.274	-789.49	0.00250	3822.9
80.80	0.05035	1.282	-797.06	0.00252	3846.2
81.20	0.05094	1.290	-804.93	0.00255	3869.7
81.60	0.05139	1.298	-813.22	0.00257	3892.8
82.00	0.05193	1.305	-821.77	0.00260	3914.2
82.40	0.05252	1.312	-830.49	0.00263	3936.8
82.80	0.05312	1.320	-839.50	0.00266	3958.9
83.20	0.05377	1.327	-849.58	0.00269	3981.0
83.60	0.05451	1.334	-859.60	0.00273	4002.4
84.00	0.05521	1.341	-869.81	0.00276	4023.1
84.40	0.05591	1.348	-880.71	0.00280	4042.9
84.80	0.05669	1.354	-892.04	0.00283	4063.2
85.20	0.05749	1.361	-904.04	0.00287	4083.4
85.60	0.05828	1.367	-916.49	0.00291	4102.1
86.00	0.05920	1.373	-928.99	0.00296	4119.7
86.40	0.06006	1.379	-942.45	0.00300	4137.3
86.80	0.06098	1.385	-956.58	0.00305	4154.8
87.20	0.06199	1.391	-971.29	0.00310	4171.7
87.60	0.06295	1.396	-986.01	0.00315	4187.6
88.00	0.06405	1.401	-1001.2	0.00320	4202.2
88.40	0.06512	1.406	-1017.5	0.00326	4217.8
88.80	0.06624	1.411	-1034.2	0.00331	4233.3
89.20	0.06749	1.416	-1052.0	0.00337	4248.6
89.60	0.06868	1.420	-1069.8	0.00343	4260.6
90.00	0.06993	1.425	-1088.2	0.00350	4273.6
90.40	0.07117	1.429	-1107.2	0.00356	4286.6
90.80	0.07255	1.433	-1126.6	0.00363	4299.2
91.20	0.07387	1.437	-1146.6	0.00369	4311.4
91.60	0.07519	1.441	-1167.0	0.00376	4322.6
92.00	0.07659	1.445	-1188.3	0.00383	4333.8
92.40	0.07808	1.448	-1209.8	0.00390	4344.6
92.80	0.07951	1.452	-1231.6	0.00398	4355.1
93.20	0.08093	1.455	-1254.1	0.00405	4365.4
93.60	0.08242	1.458	-1276.4	0.00412	4374.9
94.00	0.08397	1.461	-1299.5	0.00420	4384.4
94.40	0.08554	1.465	-1323.4	0.00428	4393.8
94.80	0.08708	1.468	-1347.5	0.00435	4403.1
95.20	0.08868	1.471	-1371.7	0.00443	4412.3
95.60	0.09030	1.473	-1396.0	0.00451	4420.0
96.00	0.09189	1.476	-1421.0	0.00459	4428.0
96.40	0.09356	1.479	-1446.1	0.00468	4436.6
96.80	0.09518	1.482	-1471.3	0.00476	4445.1
97.20	0.09669	1.484	-1496.5	0.00483	4453.1
97.60	0.09839	1.487	-1522.0	0.00492	4459.8
98.00	0.1000	1.489	-1548.5	0.00500	4466.9
98.40	0.1017	1.491	-1574.5	0.00508	4473.9
98.80	0.1034	1.494	-1601.3	0.00517	4482.2
99.20	0.1051	1.496	-1628.6	0.00526	4489.2
99.60	0.1068	1.498	-1655.9	0.00534	4494.9
100.00	0.1086	1.500	-1683.7	0.00543	4501.0
100.40	0.1103	1.503	-1711.1	0.00551	4507.9
100.80	0.1119	1.505	-1738.4	0.00560	4514.7
101.20	0.1137	1.507	-1765.6	0.00569	4520.3
101.60	0.1155	1.509	-1793.1	0.00577	4526.3
102.00	0.1172	1.511	-1821.1	0.00586	4532.6
102.40	0.1190	1.513	-1849.7	0.00595	4539.7
102.80	0.1208	1.515	-1878.9	0.00604	4545.8
103.20	0.1225	1.517	-1907.9	0.00613	4550.6
103.60	0.1243	1.518	-1937.0	0.00622	4554.9
104.00	0.1261	1.520	-1965.8	0.00630	4560.2
104.40	0.1278	1.522	-1994.8	0.00639	4567.2
104.80	0.1296	1.524	-2023.7	0.00648	4573.1
105.20	0.1314	1.526	-2052.4	0.00657	4577.4
105.60	0.1331	1.527	-2081.0	0.00666	4582.1
106.00	0.1349	1.530	-2110.1	0.00674	4588.7
106.40	0.1367	1.532	-2139.3	0.00683	4594.8
106.80	0.1384	1.533	-2168.2	0.00692	4598.8
107.20	0.1402	1.534	-2197.1	0.00701	4603.5
107.60	0.1419	1.536	-2226.6	0.00710	4608.6
108.00	0.1438	1.538	-2256.4	0.00719	4614.3
108.40	0.1456	1.540	-2286.3	0.00728	4619.4
108.80	0.1474	1.541	-2315.5	0.00737	4623.5
109.20	0.1491	1.543	-2344.9	0.00746	4627.8
109.60	0.1509	1.544	-2374.8	0.00755	4632.9
110.00	0.1527	1.546	-2404.8	0.00764	4638.2
110.40	0.1545	1.548	-2434.8	0.00773	4643.7
110.80	0.1563	1.549	-2464.4	0.00782	4647.3
111.20	0.1582	1.550	-2493.9	0.00791	4651.3
111.60	0.1599	1.552	-2523.5	0.00799	4656.6
112.00	0.1616	1.554	-2553.3	0.00808	4662.4
112.40	0.1634	1.556	-2583.7	0.00817	4666.7
112.80	0.1653	1.557	-2614.5	0.00826	4671.4
113.20	0.1671	1.558	-2645.8	0.00835	4675.3
113.60	0.1690	1.560	-2677.6	0.00845	4680.3
114.00	0.1708	1.561	-2709.1	0.00854	4684.3
114.40	0.1728	1.563	-2740.3	0.00864	4687.5
114.80	0.1746	1.564	-2771.1	0.00873	4691.5
115.20	0.1764	1.565	-2802.1	0.00882	4695.9
115.60	0.1782	1.567	-2832.2	0.00891	4701.1
116.00	0.1801	1.569	-2862.2	0.00901	4705.8
116.40	0.1819	1.570	-2891.2	0.00909	4708.7
116.80	0.1836	1.571	-2919.9	0.00918	4712.2
117.20	0.1854	1.572	-2947.8	0.00927	4716.4
117.60	0.1871	1.574	-2975.5	0.00935	4722.1
118.00	0.1888	1.575	-3002.3	0.00944	4725.8
118.40	0.1904	1.576	-3028.9	0.00952	4729.1
118.80	0.1920	1.578	-3054.6	0.00960	4732.7
119.20	0.1936	1.579	-3079.9	0.00968	4737.1
119.60	0.1951	1.580	-3104.7	0.00976	4741.5
120.00	0.1966	1.582	-3128.4	0.00983	4745.0
120.40	0.1980	1.582	-3151.4	0.00990	4747.4
120.80	0.1993	1.584	-3174.2	0.00997	4751.9
121.20	0.2007	1.586	-3197.1	0.01003	4756.7
121.60	0.2020	1.587	-3220.0	0.01010	4761.3
122.00	0.2033	1.588	-3243.1	0.01016	4765.2
122.40	0.2047	1.590	-3267.3	0.01023	4770.2
122.80	0.2062	1.592	-3293.4	0.01031	4774.8
123.20	0.2076	1.593	-3321.3	0.01038	4779.7
123.60	0.2092	1.595	-3351.4	0.01046	4783.6
124.00	0.2108	1.595	-3383.4	0.01054	4785.1
124.40	0.2126	1.596	-3418.1	0.01063	4788.0
124.80	0.2144	1.597	-3455.5	0.01072	4790.7
125.20	0.2164	1.598	-3496.7	0.01082	4794.3
125.60	0.2185	1.599	-3542.4	0.01093	4797.7
126.00	0.2208	1.600	-3593.5	0.01104	4799.0
126.40	0.2233	1.601	-3651.0	0.01116	4801.8
126.80	0.2258	1.602	-3712.5	0.01129	4804.8
127.20	0.2284	1.603	-3773.8	0.01142	4809.0
127.60	0.2310	1.604	-3828.7	0.01155	4812.1
128.00	0.2337	1.605	-3876.4	0.01169	4814.6
128.40	0.2366	1.606	-3918.8	0.01183	4817.4
128.80	0.2395	1.607	-3959.4	0.01197	4820.2
129.20	0.2424	1.608	-4007.1	0.01212	4823.3
129.60	0.2453	1.609	-4062.9	0.01226	4826.5
130.00	0.2480	1.610	-4113.2	0.01240	4831.1
130.40	0.2509	1.611	-4148.2	0.01254	4833.7
130.80	0.2552	1.586	-4152.4	0.01276	4759.2
131.20	0.2569	1.595	-4165.5	0.01285	4784.7
131.60	0.2582	1.608	-4182.5	0.01291	4825.4
132.00	0.2595	1.617	-4197.7	0.01298	4850.5
132.40	0.2615	1.586	-4183.3	0.01308	4758.4
132.80	0.2624	1.603	-4197.5	0.01312	4809.4
133.20	0.2635	1.617	-4212.1	0.01317	4850.9
133.60	0.2626	1.582	-4195.1	0.01313	4746.7
134.00	0.2634	1.600	-4207.9	0.01317	4799.4
134.40	0.2643	1.616	-4221.7	0.01321	4847.1
134.80	0.2632	1.583	-4204.7	0.01316	4748.6
135.20	0.2640	1.600	-4217.1	0.01320	4799.6
135.60	0.2649	1.616	-4230.0	0.01324	4848.9
136.00	0.2643	1.593	-4216.5	0.01321	4778.0
136.40	0.2647	1.602	-4226.1	0.01324	4807.1
136.80	0.2655	1.619	-4239.1	0.01327	4857.9
137.20	0.2647	1.592	-4224.2	0.01323	4775.9
137.60	0.2654	1.610	-4237.0	0.01327	4829.5
138.00	0.2663	1.625	-4248.8	0.01331	4874.8
138.40	0.2664	1.622	-4249.8	0.01332	4866.0
138.80	0.2667	1.619	-4250.2	0.01333	4857.4
139.20	0.2665	1.612	-4251.6	0.01333	4837.4
139.60	0.2672	1.626	-4260.4	0.01336	4878.6
140.00	0.2664	1.604	-4248.9	0.01332	4812.4
140.40	0.2672	1.621	-4260.8	0.01336	4863.9
140.80	0.2660	1.590	-4242.5	0.01330	4768.6
141.20	0.2668	1.607	-4253.9	0.01334	4821.1
141.60	0.2675	1.624	-4265.6	0.01338	4871.7
142.00	0.2663	1.591	-4246.4	0.01332	4773.9
142.40	0.2671	1.609	-4258.4	0.01335	4828.5
142.80	0.2679	1.626	-4269.3	0.01339	4877.0
143.20	0.2666	1.594	-4249.7	0.01333	4782.8
143.60	0.2674	1.613	-4261.9	0.01337	4837.6
144.00	0.2683	1.620	-4262.4	0.01341	4858.9
144.40	0.2703	1.599	-4253.8	0.01352	4798.2
144.80	0.2712	1.617	-4265.6	0.01356	4851.6
145.20	0.2773	1.602	-4253.1	0.01387	4805.8
145.60	0.2809	1.606	-4259.2	0.01404	4817.5
146.00	0.2819	1.624	-4271.5	0.01409	4872.6
146.40	0.2875	1.612	-4260.9	0.01438	4834.6
146.80	0.2915	1.612	-4265.2	0.01457	4834.8
147.20	0.2925	1.630	-4277.2	0.01463	4888.8
147.60	0.2955	1.633	-4278.3	0.01477	4898.5
148.00	0.3019	1.605	-4268.8	0.01509	4813.6
148.40	0.3021	1.604	-4269.0	0.01510	4811.7
148.80	0.3021	1.604	-4269.2	0.01511	4810.7
149.20	0.3022	1.603	-4269.4	0.01511	4809.5
149.60	0.3023	1.603	-4269.5	0.01512	4808.5
150.00	0.3022	1.602	-4269.8	0.01511	4807.4
150.40	0.3022	1.602	-4269.8	0.01511	4806.2
150.80	0.3022	1.602	-4270.1	0.01511	4805.6
151.20	0.3034	1.631	-4290.0	0.01517	4892.8
151.60	0.3142	1.611	-4277.4	0.01571	4834.0
152.00	0.3192	1.629	-4519.7	0.01596	4888.3
152.40	0.3262	1.637	-4851.7	0.01631	4911.1
152.80	0.3361	1.626	-6164.7	0.01680	4878.3
153.20	0.3454	1.617	-6279.1	0.01727	4851.4
153.60	0.3496	1.640	-6312.8	0.01748	4920.6
154.00	0.3573	1.643	-6328.4	0.01787	4929.3
154.40	0.3655	1.629	-6321.7	0.01828	4887.3
154.80	0.3720	1.634	-6326.8	0.01860	4900.8
155.20	0.3759	1.655	-6345.3	0.01880	4965.4
155.60	0.3769	1.667	-6358.5	0.01885	5002.1
156.00	0.3778	1.675	-6367.2	0.01889	5026.1
156.40	0.3779	1.671	-6371.1	0.01890	5014.3
156.80	0.3788	1.679	-6375.2	0.01894	5035.5
157.20	0.3791	1.682	-6381.6	0.01896	5044.8
157.60	0.3859	1.647	-6359.2	0.01929	4939.8
158.00	0.3894	1.647	-6359.5	0.01947	4942.3
158.40	0.3913	1.680	-6381.8	0.01956	5041.0
158.80	0.3930	1.703	-6396.9	0.01965	5108.2
159.20	0.3930	1.690	-6393.8	0.01965	5069.0
159.60	0.3924	1.668	-6382.2	0.01962	5003.1
160.00	0.3939	1.701	-6403.9	0.01970	5101.9
160.40	0.3941	1.666	-6381.4	0.01971	4998.6
160.80	0.3954	1.692	-6398.1	0.01977	5074.9
161.20	0.3960	1.701	-6406.2	0.01980	5103.4
161.60	0.3950	1.673	-6389.0	0.01975	5017.8
162.00	0.3965	1.707	-6411.2	0.01982	5119.7
162.40	0.3954	1.676	-6393.1	0.01977	5027.5
162.80	0.3969	1.709	-6415.1	0.01985	5127.0
163.20	0.3960	1.684	-6401.7	0.01980	5052.4
163.60	0.3953	1.664	-6389.9	0.01977	4992.8
164.00	0.3968	1.700	-6413.2	0.01984	5100.5
164.40	0.4022	1.673	-6396.9	0.02011	5018.9
164.80	0.4042	1.708	-6419.4	0.02021	5125.0
165.20	0.4155	1.685	-6405.5	0.02078	5055.0
165.60	0.4179	1.716	-6423.3	0.02089	5148.9
166.00	0.4293	1.695	-6414.7	0.02146	5086.4
166.40	0.4301	1.694	-6414.3	0.02151	5082.3
166.80	0.4314	1.715	-6429.4	0.02157	5145.2
167.20	0.4323	1.726	-6435.8	0.02162	5176.9
167.60	0.4436	1.700	-6427.8	0.02218	5098.9
168.00	0.4472	1.723	-6435.0	0.02236	5168.0
168.40	0.4575	1.709	-6420.3	0.02287	5127.3
168.80	0.4683	1.689	-7305.0	0.02341	5066.6
169.20	0.4705	1.724	-7430.1	0.02352	5170.9
169.60	0.4814	1.705	-8750.4	0.02407	5115.6
170.00	0.4915	1.691	-8792.8	0.02457	5073.6
170.40	0.4941	1.725	-8836.4	0.02470	5174.1
170.80	0.5065	1.695	-8832.6	0.02533	5084.8
171.20	0.5094	1.725	-8855.6	0.02547	5176.4
171.60	0.5187	1.718	-8857.2	0.02593	5155.4
172.00	0.5269	1.712	-8855.9	0.02634	5136.7
172.40	0.5288	1.740	-8876.2	0.02644	5221.4
172.80	0.5283	1.716	-8864.0	0.02641	5148.0
173.20	0.5296	1.744	-8883.3	0.02648	5232.7
173.60	0.5295	1.739	-8881.8	0.02647	5215.9
174.00	0.5287	1.712	-8866.8	0.02643	5136.5
174.40	0.5300	1.745	-8889.1	0.02650	5233.6
174.80	0.5310	1.765	-8902.8	0.02655	5294.3
175.20	0.5300	1.734	-8886.8	0.02650	5203.5
175.60	0.5314	1.765	-8906.9	0.02657	5294.0
176.00	0.5369	1.711	-8873.6	0.02685	5133.1
176.40	0.5386	1.747	-8896.4	0.02693	5240.0
176.80	0.5428	1.730	-8885.2	0.02714	5191.4
177.20	0.5446	1.763	-8906.0	0.02723	5289.3
177.60	0.5500	1.759	-8902.9	0.02750	5276.6
178.00	0.5497	1.734	-8885.2	0.02748	5203.4
178.40	0.5509	1.761	-8905.7	0.02754	5284.3
178.80	0.5505	1.724	-8883.5	0.02753	5172.4
179.20	0.5521	1.760	-8906.5	0.02760	5279.9
179.60	0.5512	1.734	-8890.4	0.02756	5203.3
180.00	0.5526	1.769	-8913.0	0.02763	5308.4
180.40	0.5511	1.732	-8891.4	0.02756	5194.8
180.80	0.5526	1.766	-8913.5	0.02763	5299.4
181.20	0.5520	1.747	-8899.1	0.02760	5241.3
181.60	0.5528	1.768	-8916.6	0.02764	5302.9
182.00	0.5519	1.738	-8899.3	0.02760	5214.4
182.40	0.5536	1.775	-8922.7	0.02768	5325.2
182.80	0.5539	1.763	-8915.3	0.02770	5288.4
183.20	0.5569	1.780	-8923.5	0.02784	5339.7
183.60	0.5646	1.765	-8919.9	0.02823	5296.5
184.00	0.5739	1.753	-8910.8	0.02869	5260.0
184.40	0.5784	1.776	-8928.8	0.02892	5327.6
184.80	0.5819	1.771	-8913.0	0.02909	5313.1
185.20	0.5860	1.781	-8927.7	0.02930	5344.0
185.60	0.5951	1.772	-8926.4	0.02976	5314.9
186.00	0.5981	1.797	-8941.6	0.02991	5390.4
186.40	0.6086	1.780	-8940.8	0.03043	5340.6
186.80	0.6129	1.795	-8942.7	0.03065	5384.4
187.20	0.6234	1.781	-8937.5	0.03117	5342.1
187.60	0.6332	1.766	-10082	0.03166	5297.7
188.00	0.6378	1.788	-10330	0.03189	5364.0
188.40	0.6498	1.761	-11655	0.03249	5283.4
188.80	0.6522	1.795	-11722	0.03261	5384.9
189.20	0.6647	1.765	-11720	0.03324	5293.6
189.60	0.6668	1.800	-11757	0.03334	5401.2
190.00	0.6663	1.762	-11741	0.03332	5287.2
190.40	0.6680	1.798	-11769	0.03340	5394.4
190.80	0.6686	1.802	-11777	0.03343	5404.6
191.20	0.6697	1.819	-11788	0.03349	5457.1
191.60	0.6696	1.805	-11784	0.03348	5415.6
192.00	0.6704	1.810	-11787	0.03352	5430.8
192.40	0.6714	1.825	-11799	0.03357	5473.9
192.80	0.6863	1.778	-11775	0.03431	5334.6
193.20	0.6886	1.812	-11798	0.03443	5435.7
193.60	0.7004	1.786	-11783	0.03502	5359.3
194.00	0.7026	1.821	-11806	0.03513	5462.6
194.40	0.7048	1.825	-11806	0.03524	5475.7
194.80	0.7053	1.785	-11787	0.03526	5355.6
195.20	0.7067	1.817	-11809	0.03534	5450.3
195.60	0.7083	1.843	-11828	0.03541	5529.9
196.00	0.7071	1.807	-11808	0.03536	5420.9
196.40	0.7068	1.796	-11795	0.03534	5389.5
196.80	0.7072	1.805	-11808	0.03536	5415.2
197.20	0.7087	1.838	-11830	0.03543	5514.5
197.60	0.7076	1.803	-11810	0.03538	5410.3
198.00	0.7091	1.838	-11832	0.03545	5514.4
198.40	0.7069	1.777	-11793	0.03535	5330.0
198.80	0.7085	1.815	-11817	0.03542	5443.8
199.20	0.7098	1.843	-11834	0.03549	5530.1
199.60	0.7089	1.821	-11822	0.03545	5463.6
200.00	0.7105	1.854	-11844	0.03553	5562.8
200.40	0.7142	1.804	-11812	0.03571	5411.7
200.80	0.7161	1.837	-11831	0.03580	5509.6
201.20	0.7202	1.811	-11816	0.03601	5433.2
201.60	0.7242	1.800	-11806	0.03621	5401.0
202.00	0.7264	1.829	-11826	0.03632	5485.7
202.40	0.7271	1.834	-11821	0.03636	5500.8
202.80	0.7268	1.821	-11821	0.03634	5462.4
203.20	0.7285	1.855	-11843	0.03642	5565.7
203.60	0.7289	1.860	-11844	0.03645	5579.9
204.00	0.7292	1.861	-11849	0.03646	5582.7
204.40	0.7440	1.810	-11831	0.03720	5430.9
204.80	0.7462	1.846	-11853	0.03731	5536.6
205.20	0.7563	1.827	-11842	0.03782	5482.0
205.60	0.7608	1.850	-11861	0.03804	5550.3
206.00	0.7667	1.857	-11859	0.03833	5570.4
206.40	0.7767	1.846	-11859	0.03884	5536.8
206.80	0.7790	1.877	-11878	0.03895	5630.2
207.20	0.7931	1.836	-11817	0.03965	5508.5
207.60	0.7953	1.870	-11860	0.03977	5610.7
208.00	0.8092	1.828	-13149	0.04046	5485.0
208.40	0.8113	1.864	-13224	0.04057	5591.3
208.80	0.8135	1.800	-13298	0.04068	5399.2
209.20	0.8153	1.835	-13328	0.04077	5506.3
209.60	0.8148	1.809	-13318	0.04074	5426.9
210.00	0.8163	1.841	-13343	0.04081	5522.0
210.40	0.8172	1.855	-13353	0.04086	5564.4
210.80	0.8173	1.855	-13362	0.04086	5563.5
211.20	0.8296	1.815	-13341	0.04148	5445.6
211.60	0.8325	1.846	-13364	0.04162	5538.8
212.00	0.8346	1.880	-13393	0.04173	5639.1
212.40	0.8482	1.842	-13392	0.04241	5526.1
212.80	0.8506	1.875	-13416	0.04253	5624.9
213.20	0.8513	1.865	-13410	0.04257	5595.6
213.60	0.8640	1.835	-14076	0.04320	5503.5
214.00	0.8662	1.870	-14158	0.04331	5608.6
214.40	0.8776	1.835	-14247	0.04388	5505.2
214.80	0.8813	1.861	-14279	0.04407	5583.5
215.20	0.8839	1.891	-14323	0.04420	5673.2
215.60	0.8985	1.847	-14307	0.04493	5541.6
216.00	0.9007	1.882	-14337	0.04503	5646.3
216.40	0.9020	1.850	-14323	0.04510	5550.5
216.80	0.9029	1.865	-14341	0.04515	5596.3
217.20	0.9047	1.895	-14368	0.04523	5684.3
217.60	0.9037	1.859	-14353	0.04519	5577.6
218.00	0.9049	1.886	-14376	0.04525	5659.0
218.40	0.9062	1.906	-14395	0.04531	5718.3
218.80	0.9062	1.903	-14400	0.04531	5707.6
219.20	0.9051	1.871	-14385	0.04525	5613.5
219.60	0.9066	1.902	-14409	0.04533	5707.0
220.00	0.9062	1.889	-14405	0.04531	5667.3
220.40	0.9076	1.917	-14430	0.04538	5752.1
220.80	0.9073	1.905	-14428	0.04536	5714.3
221.20	0.9055	1.856	-14401	0.04527	5567.8
221.60	0.9069	1.891	-14425	0.04534	5671.5
222.00	0.9062	1.869	-14411	0.04531	5606.5
222.40	0.9070	1.889	-14429	0.04535	5667.6
222.80	0.9084	1.918	-14452	0.04542	5754.9
223.20	0.9074	1.891	-14437	0.04537	5672.8
223.60	0.9089	1.923	-14461	0.04544	5767.9
224.00	0.9073	1.854	-14423	0.04536	5562.5
224.40	0.9088	1.891	-14447	0.04544	5671.8
224.80	0.9124	1.861	-14426	0.04562	5582.2
225.20	0.9144	1.886	-14446	0.04572	5657.8
225.60	0.9181	1.854	-14423	0.04591	5562.8
226.00	0.9198	1.885	-14445	0.04599	5654.9
226.40	0.9245	1.868	-14430	0.04623	5602.9
226.80	0.9269	1.894	-14450	0.04635	5681.7
227.20	0.9287	1.926	-14474	0.04644	5777.6
227.60	0.9349	1.920	-14491	0.04674	5758.6
228.00	0.9490	1.874	-14474	0.04745	5623.0
228.40	0.9516	1.907	-14497	0.04758	5721.5
228.80	0.9549	1.930	-14514	0.04775	5790.1
229.20	0.9684	1.896	-14637	0.04842	5689.2
229.60	0.9803	1.871	-16483	0.04901	5612.1
230.00	0.9844	1.896	-16714	0.04922	5687.5
230.40	0.9867	1.930	-16801	0.04933	5790.3
230.80	0.9995	1.892	-18144	0.04997	5675.5
231.20	1.003	1.922	-18240	0.05014	5765.2
231.60	1.015	1.897	-18261	0.05074	5690.6
232.00	1.017	1.931	-18305	0.05085	5793.9
232.40	1.032	1.886	-18304	0.05159	5658.4
232.80	1.034	1.922	-18332	0.05170	5765.1
233.20	1.050	1.867	-18298	0.05251	5602.3
233.60	1.054	1.893	-18319	0.05271	5677.7
234.00	1.057	1.925	-18345	0.05284	5775.0
234.40	1.071	1.887	-18327	0.05353	5662.0
234.80	1.074	1.921	-18351	0.05368	5761.7
235.20	1.085	1.898	-18342	0.05426	5693.9
235.60	1.088	1.933	-18366	0.05438	5798.4
236.00	1.098	1.864	-18325	0.05491	5591.1
236.40	1.100	1.899	-18349	0.05501	5697.6
236.80	1.101	1.896	-18341	0.05503	5687.5
237.20	1.101	1.897	-18349	0.05505	5691.8
237.60	1.103	1.926	-18366	0.05513	5777.9
238.00	1.102	1.902	-18355	0.05508	5706.7
238.40	1.103	1.935	-18378	0.05516	5804.9
238.80	1.101	1.882	-18346	0.05505	5646.1
239.20	1.103	1.917	-18369	0.05514	5750.7
239.60	1.102	1.890	-18354	0.05508	5670.2
240.00	1.103	1.926	-18378	0.05516	5777.4
240.40	1.106	1.907	-18387	0.05529	5722.3
240.80	1.107	1.919	-18395	0.05534	5756.1
241.20	1.106	1.895	-18381	0.05531	5685.4
241.60	1.108	1.930	-18404	0.05539	5788.7
242.00	1.115	1.924	-18363	0.05575	5772.2
242.40	1.117	1.913	-18364	0.05585	5739.7
242.80	1.118	1.925	-18379	0.05589	5773.9
243.20	1.120	1.946	-18396	0.05598	5838.9
243.60	1.121	1.950	-18398	0.05606	5850.1
244.00	1.135	1.901	-18362	0.05673	5702.7
244.40	1.137	1.934	-18384	0.05684	5801.5
244.80	1.138	1.924	-18377	0.05690	5770.8
245.20	1.138	1.920	-18383	0.05690	5760.4
245.60	1.140	1.952	-18404	0.05699	5855.3
246.00	1.139	1.923	-18387	0.05694	5767.8
246.40	1.140	1.956	-18410	0.05702	5868.5
246.80	1.151	1.914	-18365	0.05754	5743.0
247.20	1.154	1.941	-18385	0.05770	5821.9
247.60	1.160	1.910	-18365	0.05800	5731.3
248.00	1.163	1.935	-18385	0.05814	5805.7
248.40	1.166	1.947	-18386	0.05829	5841.8
248.80	1.171	1.930	-18382	0.05855	5788.8
249.20	1.173	1.961	-18404	0.05864	5883.7
249.60	1.176	1.925	-18382	0.05881	5775.4
250.00	1.178	1.959	-18404	0.05890	5876.3
250.40	1.177	1.917	-18379	0.05885	5752.0
250.80	1.179	1.952	-18402	0.05893	5856.3
251.20	1.177	1.911	-18378	0.05886	5733.0
251.60	1.179	1.947	-18401	0.05893	5839.5
252.00	1.177	1.909	-18378	0.05887	5728.1
252.40	1.179	1.942	-18401	0.05894	5827.2
252.80	1.179	1.947	-18399	0.05896	5839.7
253.20	1.179	1.939	-18403	0.05895	5818.3
253.60	1.181	1.971	-18425	0.05903	5912.3
254.00	1.179	1.938	-18408	0.05897	5814.5
254.40	1.181	1.971	-18431	0.05904	5913.7
254.80	1.195	1.925	-18392	0.05973	5774.4
255.20	1.197	1.959	-18415	0.05983	5876.0
255.60	1.198	1.955	-18417	0.05992	5865.3
256.00	1.200	1.974	-18430	0.06001	5921.6
256.40	1.199	1.925	-18402	0.05995	5775.1
256.80	1.201	1.957	-18424	0.06003	5869.9
257.20	1.202	1.979	-18435	0.06010	5937.9
257.60	1.201	1.952	-18424	0.06005	5856.7
258.00	1.203	1.984	-18445	0.06014	5951.1
258.40	1.202	1.956	-18429	0.06008	5867.0
258.80	1.203	1.987	-18451	0.06017	5961.7
259.20	1.203	1.965	-18444	0.06015	5896.1
259.60	1.209	1.972	-18436	0.06043	5915.1
260.00	1.220	1.947	-18423	0.06102	5839.6
260.40	1.223	1.976	-18445	0.06116	5927.4
260.80	1.236	1.935	-18425	0.06178	5804.3
261.20	1.238	1.968	-18446	0.06189	5904.6
261.60	1.243	1.925	-18416	0.06213	5773.6
262.00	1.244	1.960	-18440	0.06222	5880.8
262.40	1.244	1.938	-18420	0.06220	5813.3
262.80	1.245	1.955	-18436	0.06225	5865.1
263.20	1.246	1.974	-18442	0.06231	5923.2
263.60	1.245	1.947	-18429	0.06224	5840.4
264.00	1.246	1.980	-18452	0.06232	5939.1
264.40	1.245	1.939	-18427	0.06225	5817.4
264.80	1.247	1.973	-18449	0.06233	5919.7
265.20	1.245	1.933	-18422	0.06225	5799.4
265.60	1.247	1.969	-18445	0.06233	5905.6
266.00	1.248	1.984	-18456	0.06238	5950.7
266.40	1.247	1.966	-18439	0.06235	5898.4
266.80	1.247	1.963	-18443	0.06234	5888.5
267.20	1.248	1.993	-18464	0.06242	5980.5
267.60	1.247	1.957	-18440	0.06234	5870.4
268.00	1.249	1.991	-18462	0.06243	5972.1
268.40	1.263	1.935	-18434	0.06313	5805.2
268.80	1.265	1.968	-18456	0.06326	5903.8
269.20	1.278	1.931	-18438	0.06392	5792.0
269.60	1.281	1.965	-18460	0.06403	5895.7
270.00	1.294	1.929	-18427	0.06468	5786.1
270.40	1.296	1.961	-18452	0.06482	5883.6
270.80	1.306	1.950	-18786	0.06528	5848.6
271.20	1.312	1.956	-18982	0.06562	5867.2
271.60	1.316	1.982	-19453	0.06579	5946.7
272.00	1.328	1.950	-21063	0.06642	5850.1
272.40	1.331	1.983	-21208	0.06655	5950.5
272.80	1.344	1.945	-22685	0.06721	5836.0
273.20	1.347	1.979	-22741	0.06734	5938.1
273.60	1.360	1.938	-22791	0.06802	5814.7
274.00	1.363	1.973	-22837	0.06813	5919.4
274.40	1.377	1.932	-22817	0.06883	5795.3
274.80	1.379	1.967	-22845	0.06894	5902.4
275.20	1.392	1.927	-22835	0.06962	5781.8
275.60	1.395	1.962	-22862	0.06974	5886.2
276.00	1.398	1.981	-22888	0.06990	5943.1
276.40	1.404	1.973	-22897	0.07022	5919.5
276.80	1.418	1.932	-22877	0.07090	5796.8
277.20	1.420	1.967	-22901	0.07101	5902.2
277.60	1.433	1.936	-22879	0.07163	5809.1
278.00	1.436	1.964	-22901	0.07180	5893.3
278.40	1.438	1.996	-22923	0.07192	5987.9
278.80	1.439	1.987	-22923	0.07196	5961.4
279.20	1.444	1.987	-22919	0.07222	5961.2
279.60	1.455	1.964	-22909	0.07274	5890.7
280.00	1.457	1.997	-22932	0.07286	5991.3
280.40	1.466	1.954	-22904	0.07332	5862.3
280.80	1.468	1.989	-22927	0.07342	5967.1
281.20	1.474	1.962	-22906	0.07371	5885.1
281.60	1.477	1.980	-22922	0.07387	5941.4
282.00	1.479	1.997	-22932	0.07394	5991.5
282.40	1.480	2.010	-22944	0.07400	6029.9
282.80	1.486	1.953	-22908	0.07428	5858.9
283.20	1.488	1.987	-22932	0.07438	5961.8
283.60	1.491	1.958	-22910	0.07456	5875.4
284.00	1.494	1.978	-22928	0.07470	5932.7
284.40	1.496	2.008	-22948	0.07478	6023.4
284.80	1.495	1.965	-22923	0.07474	5896.3
285.20	1.497	1.999	-22946	0.07483	5998.4
285.60	1.495	1.957	-22921	0.07475	5872.2
286.00	1.497	1.992	-22945	0.07484	5977.2
286.40	1.496	1.960	-22927	0.07479	5879.8
286.80	1.497	1.985	-22947	0.07487	5955.7
287.20	1.500	2.005	-22968	0.07500	6015.4
287.60	1.505	2.005	-22967	0.07523	6014.5
288.00	1.509	2.002	-22969	0.07544	6006.0
288.40	1.512	1.998	-22968	0.07560	5994.7
288.80	1.512	1.982	-22965	0.07559	5947.3
289.20	1.514	2.012	-22986	0.07568	6036.2
289.60	1.520	1.990	-22978	0.07601	5970.4
290.00	1.525	2.006	-22991	0.07625	6017.2
290.40	1.536	1.980	-22926	0.07681	5941.0
290.80	1.540	2.008	-22953	0.07698	6025.2
291.20	1.555	1.957	-22942	0.07774	5869.9
291.60	1.557	1.991	-22967	0.07786	5972.5
292.00	1.569	1.959	-22943	0.07846	5877.5
292.40	1.574	1.978	-22961	0.07871	5935.5
292.80	1.577	2.010	-22982	0.07884	6030.8
293.20	1.590	1.974	-22957	0.07950	5921.7
293.60	1.592	2.008	-22980	0.07961	6023.3
294.00	1.606	1.963	-22949	0.08031	5887.9
294.40	1.608	1.998	-22974	0.08042	5993.5
294.80	1.617	1.980	-22957	0.08084	5940.0
295.20	1.623	1.989	-22969	0.08113	5968.3
295.60	1.625	2.021	-22991	0.08123	6062.0
296.00	1.630	1.980	-22965	0.08148	5940.4
296.40	1.631	2.013	-22988	0.08157	6040.2
296.80	1.632	2.012	-22994	0.08160	6034.9
297.20	1.630	1.964	-22959	0.08151	5892.0
297.60	1.632	1.997	-22982	0.08160	5991.1
298.00	1.631	1.983	-22966	0.08157	5950.1
298.40	1.632	1.986	-22975	0.08158	5958.9
298.80	1.633	2.018	-22997	0.08166	6052.9
299.20	1.631	1.977	-22971	0.08157	5930.6
299.60	1.633	2.011	-22995	0.08165	6032.3
300.00	1.632	1.969	-22982	0.08159	5907.0
300.40	1.633	2.001	-23006	0.08166	6004.4
300.80	1.638	2.006	-23317	0.08189	6018.5
301.20	1.645	2.004	-23900	0.08223	6013.2
301.60	1.657	1.974	-25479	0.08285	5922.7
302.00	1.660	2.006	-25595	0.08298	6019.5
302.40	1.674	1.962	-27290	0.08369	5887.1
302.80	1.676	1.997	-27367	0.08380	5991.2
303.20	1.687	1.973	-27572	0.08435	5919.4
303.60	1.693	1.988	-27673	0.08464	5963.4
304.00	1.695	2.019	-27730	0.08477	6055.7
304.40	1.709	1.978	-27687	0.08545	5934.0
304.80	1.711	2.012	-27718	0.08557	6035.2
305.20	1.726	1.967	-27710	0.08629	5900.7
305.60	1.728	2.001	-27736	0.08641	6004.3
306.00	1.742	1.960	-27725	0.08710	5878.8
306.40	1.744	1.995	-27750	0.08721	5983.8
306.80	1.747	2.018	-27775	0.08736	6055.3
307.20	1.758	1.987	-27765	0.08788	5962.1
307.60	1.760	2.018	-27789	0.08802	6054.1
308.00	1.775	1.975	-27764	0.08873	5925.3
308.40	1.777	2.009	-27787	0.08885	6026.4
308.80	1.789	1.976	-27765	0.08944	5928.4
309.20	1.793	1.997	-27783	0.08966	5992.0
309.60	1.796	2.029	-27805	0.08978	6086.0
310.00	1.808	1.986	-27776	0.09042	5957.5
310.40	1.811	2.020	-27799	0.09053	6058.6
310.80	1.819	1.974	-27767	0.09097	5921.8
311.20	1.822	2.007	-27790	0.09109	6022.1
311.60	1.826	2.015	-27786	0.09128	6043.6
312.00	1.831	1.997	-27781	0.09157	5990.3
312.40	1.834	2.028	-27802	0.09168	6084.9
312.80	1.841	1.984	-27769	0.09207	5952.0
313.20	1.843	2.017	-27791	0.09217	6052.4
313.60	1.850	1.977	-27759	0.09250	5929.8
314.00	1.852	2.007	-27780	0.09261	6019.7
314.40	1.854	2.031	-27789	0.09272	6092.0
314.80	1.857	1.997	-27763	0.09285	5991.1
315.20	1.859	2.029	-27788	0.09294	6086.3
315.60	1.863	2.021	-27992	0.09316	6064.4
316.00	1.863	1.963	-28100	0.09313	5890.4
316.40	1.864	1.996	-28132	0.09321	5986.6
316.80	1.866	2.025	-28167	0.09328	6073.5
317.20	1.864	1.984	-28152	0.09322	5951.2
317.60	1.866	2.016	-28179	0.09329	6047.2
318.00	1.866	2.007	-28179	0.09330	6020.9
318.40	1.866	1.999	-28184	0.09328	5996.7
318.80	1.867	2.030	-28210	0.09335	6089.0
319.20	1.865	1.982	-28185	0.09326	5947.3
319.60	1.867	2.016	-28211	0.09334	6048.1
320.00	1.866	2.002	-28201	0.09331	6005.5
320.40	1.867	2.011	-28216	0.09333	6034.2
320.80	1.868	2.042	-28241	0.09342	6127.2
321.20	1.867	2.015	-28230	0.09336	6044.5
321.60	1.866	1.975	-28206	0.09329	5923.7
322.00	1.867	2.007	-28229	0.09336	6021.3
322.40	1.869	2.034	-28251	0.09343	6103.3
322.80	1.867	1.991	-28226	0.09334	5974.4
323.20	1.868	2.025	-28251	0.09341	6074.2
323.60	1.867	1.980	-28227	0.09333	5940.4
324.00	1.868	2.011	-28250	0.09340	6032.6
324.40	1.870	2.039	-28274	0.09348	6116.7
324.80	1.868	1.997	-28255	0.09339	5991.9
325.20	1.869	2.030	-28280	0.09346	6090.7
325.60	1.868	1.990	-28273	0.09342	5968.7
326.00	1.870	2.024	-28299	0.09349	6070.7
326.40	1.872	2.044	-28373	0.09360	6133.3
326.80	1.881	2.029	-28577	0.09405	6086.6
327.20	1.897	1.982	-28502	0.09483	5945.8
327.60	1.899	2.016	-28542	0.09495	6047.2
328.00	1.903	2.041	-28611	0.09513	6123.0
328.40	1.917	2.003	-28620	0.09584	6008.1
328.80	1.920	2.035	-28653	0.09598	6105.4
329.20	1.935	1.989	-28643	0.09675	5965.7
329.60	1.937	2.022	-28671	0.09686	6064.9
330.00	1.948	2.000	-28664	0.09742	5999.2
330.40	1.955	2.009	-28680	0.09776	6025.9
330.80	1.958	2.039	-28708	0.09792	6118.5
331.20	1.973	1.998	-28685	0.09866	5992.6
331.60	1.976	2.031	-28713	0.09879	6092.0
332.00	1.991	1.989	-28706	0.09953	5965.5
332.40	1.993	2.022	-28735	0.09965	6066.4
332.80	2.000	2.021	-28831	0.1000	6063.9
333.20	2.009	2.016	-28846	0.1004	6048.5
333.60	2.021	1.985	-28864	0.1011	5955.7
334.00	2.027	1.998	-28883	0.1014	5994.5
334.40	2.030	2.028	-28917	0.1015	6083.7
334.80	2.045	1.986	-28899	0.1022	5959.1
335.20	2.047	2.019	-28928	0.1023	6057.1
335.60	2.062	1.975	-28916	0.1031	5925.7
336.00	2.064	2.009	-28942	0.1032	6025.9
336.40	2.074	1.992	-28942	0.1037	5977.4
336.80	2.081	2.000	-28959	0.1040	6001.1
337.20	2.084	2.031	-28987	0.1042	6093.0
337.60	2.098	1.992	-28959	0.1049	5974.5
338.00	2.100	2.025	-28999	0.1050	6073.8
338.40	2.115	1.982	-29433	0.1057	5946.8
338.80	2.117	2.016	-29508	0.1059	6046.9
339.20	2.122	2.032	-30124	0.1061	6096.2
339.60	2.134	2.004	-31404	0.1067	6010.5
340.00	2.137	2.034	-31538	0.1068	6103.2
340.40	2.151	1.992	-33499	0.1075	5976.5
340.80	2.153	2.025	-33598	0.1077	6075.0
341.20	2.167	1.982	-34168	0.1084	5945.7
341.60	2.170	2.014	-34246	0.1085	6042.4
342.00	2.180	1.996	-34242	0.1090	5989.1
342.40	2.186	2.008	-34257	0.1093	6022.9
342.80	2.189	2.037	-34298	0.1094	6110.0
343.20	2.203	1.998	-34288	0.1101	5994.1
343.60	2.205	2.031	-34316	0.1103	6092.2
344.00	2.219	1.988	-34303	0.1110	5963.8
344.40	2.222	2.021	-34330	0.1111	6063.0
344.80	2.234	1.988	-34324	0.1117	5964.4
345.20	2.239	2.009	-34346	0.1119	6027.1
345.60	2.242	2.039	-34373	0.1121	6118.3
346.00	2.251	2.031	-34387	0.1126	6093.0
346.40	2.261	2.027	-34391	0.1130	6080.3
346.80	2.272	2.007	-34357	0.1136	6021.3
347.20	2.278	2.024	-34378	0.1139	6072.5
347.60	2.292	1.987	-34357	0.1146	5961.0
348.00	2.295	2.018	-34381	0.1147	6055.3
348.40	2.310	1.976	-34364	0.1155	5926.7
348.80	2.313	2.006	-34388	0.1156	6017.2
349.20	2.316	2.032	-34403	0.1158	6096.1
349.60	2.331	1.996	-34392	0.1165	5986.8
350.00	2.333	2.027	-34409	0.1167	6082.4
350.40	2.349	1.987	-34486	0.1174	5959.9
350.80	2.351	2.019	-34547	0.1175	6058.5
351.20	2.365	1.984	-35736	0.1182	5953.5
351.60	2.369	2.011	-35883	0.1185	6031.6
352.00	2.372	2.038	-36101	0.1186	6114.3
352.40	2.387	1.999	-38152	0.1194	5996.6
352.80	2.390	2.031	-38258	0.1195	6093.6
353.20	2.406	1.987	-39651	0.1203	5960.2
353.60	2.409	2.018	-39786	0.1204	6053.8
354.00	2.418	2.009	-41084	0.1209	6027.7
354.40	2.428	2.006	-41851	0.1214	6017.2
354.80	2.431	2.036	-41954	0.1215	6107.9
355.20	2.445	1.997	-42340	0.1223	5990.4
355.60	2.448	2.029	-42427	0.1224	6086.5
356.00	2.462	1.991	-42485	0.1231	5973.5
356.40	2.465	2.023	-42523	0.1233	6068.4
356.80	2.473	2.015	-42557	0.1236	6046.3
357.20	2.488	1.967	-42506	0.1244	5901.6
357.60	2.491	2.000	-42528	0.1246	5999.4
358.00	2.498	2.004	-42472	0.1249	6012.4
358.40	2.508	1.993	-42493	0.1254	5978.6
358.80	2.511	2.021	-42554	0.1256	6062.0
359.20	2.526	1.980	-42558	0.1263	5940.1
359.60	2.528	2.012	-42583	0.1264	6036.7
360.00	2.543	1.969	-42543	0.1271	5908.0
360.40	2.545	2.001	-42589	0.1273	6002.8
360.80	2.558	1.966	-42628	0.1279	5897.8
361.20	2.562	1.993	-42654	0.1281	5978.1
361.60	2.568	1.999	-42633	0.1284	5996.9
362.00	2.578	1.985	-42626	0.1289	5956.1
362.40	2.582	2.012	-42663	0.1291	6034.5
362.80	2.595	1.978	-42661	0.1297	5934.4
363.20	2.598	2.009	-42680	0.1299	6027.2
363.60	2.611	1.973	-42634	0.1306	5919.0
364.00	2.614	2.004	-42666	0.1307	6012.4
364.40	2.627	1.968	-42664	0.1314	5904.0
364.80	2.630	1.999	-42684	0.1315	5998.5
365.20	2.643	1.963	-42638	0.1322	5890.1
365.60	2.646	1.995	-42665	0.1323	5984.5
366.00	2.660	1.960	-42661	0.1330	5880.2
366.40	2.663	1.992	-42680	0.1331	5974.7
366.80	2.675	1.958	-42643	0.1338	5873.0
367.20	2.679	1.987	-42667	0.1339	5961.2
367.60	2.691	1.956	-42664	0.1346	5867.7
368.00	2.697	1.967	-42657	0.1349	5900.6
368.40	2.707	1.956	-42652	0.1353	5866.6
368.80	2.718	1.934	-42649	0.1359	5802.3
369.20	2.722	1.956	-42671	0.1361	5868.8
369.60	2.735	1.924	-42639	0.1368	5772.5
370.00	2.738	1.957	-42663	0.1369	5869.7
370.40	2.751	1.927	-42659	0.1375	5780.9
370.80	2.754	1.953	-42670	0.1377	5859.4
371.20	2.766	1.930	-42657	0.1383	5791.2
371.60	2.777	1.908	-42653	0.1388	5724.7
372.00	2.780	1.933	-42674	0.1390	5800.4
372.40	2.792	1.904	-42649	0.1396	5712.7
372.80	2.795	1.933	-42672	0.1398	5800.0
373.20	2.807	1.909	-42669	0.1404	5726.2
373.60	2.818	1.886	-42645	0.1409	5657.1
374.00	2.821	1.914	-42670	0.1411	5743.0
374.40	2.833	1.889	-42665	0.1416	5666.7
374.80	2.842	1.879	-42649	0.1421	5638.1
375.20	2.847	1.895	-42668	0.1424	5684.3
375.60	2.859	1.871	-42663	0.1429	5613.1
376.00	2.867	1.864	-42647	0.1434	5591.9
376.40	2.873	1.880	-42666	0.1436	5638.7
376.80	2.884	1.855	-42660	0.1442	5566.2
377.20	2.894	1.840	-42642	0.1447	5520.5
377.60	2.898	1.863	-42663	0.1449	5590.4
378.00	2.909	1.841	-42655	0.1454	5523.4
378.40	2.919	1.820	-42636	0.1460	5459.0
378.80	2.924	1.840	-42649	0.1462	5518.7
379.20	2.933	1.829	-42652	0.1467	5487.8
379.60	2.944	1.808	-42634	0.1472	5423.4
380.00	2.954	1.791	-42625	0.1477	5373.5
380.40	2.958	1.811	-42634	0.1479	5434.4
380.80	2.968	1.799	-42631	0.1484	5396.2
381.20	2.979	1.779	-42622	0.1489	5337.8
381.60	2.989	1.760	-42605	0.1494	5280.8
382.00	2.997	1.759	-42602	0.1498	5275.8
382.40	3.003	1.770	-42612	0.1501	5309.7
382.80	3.013	1.754	-42603	0.1506	5263.2
383.20	3.023	1.736	-42593	0.1512	5208.7
383.60	3.033	1.719	-42579	0.1517	5155.9
384.00	3.043	1.702	-42566	0.1522	5105.2
384.40	3.052	1.696	-42557	0.1526	5087.4
384.80	3.059	1.691	-42557	0.1530	5073.8
385.20	3.248	0.8471	-41733	0.1624	2541.3
385.60	3.400	0.00305	-41288	0.1700	9.152
386.00	3.408	0.00313	-41290	0.1704	9.399
386.40	3.416	0.00314	-41291	0.1708	9.433
386.80	3.424	0.00313	-41292	0.1712	9.377
387.20	3.432	0.00315	-41293	0.1716	9.446
387.60	3.440	0.00310	-41293	0.1720	9.291
388.00	3.449	0.00317	-41293	0.1724	9.520
388.40	3.457	0.00315	-41294	0.1728	9.455
388.80	3.465	0.00315	-41294	0.1732	9.442
389.20	3.473	0.00320	-41294	0.1736	9.606
389.60	3.481	0.00317	-41294	0.1740	9.520
390.00	3.489	0.00315	-41294	0.1744	9.464
390.40	3.497	0.00333	-41295	0.1748	9.987
390.80	3.505	0.00320	-41295	0.1752	9.598
391.20	3.512	0.00328	-41295	0.1756	9.836
391.60	3.512	0.00326	-41295	0.1756	9.792
392.00	3.513	0.00323	-41295	0.1756	9.676
392.40	3.513	0.00313	-41295	0.1756	9.390
392.80	3.513	0.00316	-41296	0.1756	9.490
393.20	3.513	0.00314	-41296	0.1756	9.433
393.60	3.513	0.00314	-41296	0.1756	9.421
393.80	3.513	0.00325	-41296	0.1756	9.736