File: Laboratory Exercise 3 Standardized Testing report and discussion/Group5_Al_DAQ.txt
File Path: C:\Measurements\Harkka\Test Run 1 05-8-24 11 22 18 am\DAQ- Crosshead, … - (Timed).txt
Test: KW-VETO_ext_2speed_Aout_verified_gr5
Test Run: Test Run 1
Date: 08/05/2024 11.04.41


Crosshead 	Load 	Time 	Extensometer
mm	N	sec	mm/mm
0.000400000004674439	152.741104125977	1.80299997329712	7.93368508311687E-06
0.00230000000556174	172.920288085938	2.00300002098083	2.29719262279104E-05
0.00460000001112348	198.846115112305	2.20300006866455	3.02865628327709E-05
0.00709999994796817	225.746154785156	2.40300011634827	4.88800942548551E-05
0.00949999957811087	251.626983642578	2.6029999256134	6.50324873276986E-05
0.0118999996630009	276.827117919922	2.80299997329712	8.19899214548059E-05
0.0146000002132496	302.000701904297	3.00300002098083	0.000101272969914135
0.0170000002981396	327.243286132813	3.20300006866455	0.000114643102278933
0.0194999993254896	350.572906494141	3.40300011634827	0.000124460144434124
0.0220999991142889	372.627899169922	3.6029999256134	0.000141452896059491
0.0245999999606283	394.147979736328	3.80299997329712	0.000157273883814923
0.0271000008069677	415.914703369141	4.00299978256226	0.000166805635672063
0.0295000008918578	435.248016357422	4.20300006866455	0.000185856071766466
0.0321000006806571	455.972961425781	4.40299987792969	0.000188664183951914
0.0346000015269965	475.781097412109	4.60300016403198	0.000208473837119527
0.0370000016118865	495.304504394531	4.80299997329712	0.000221306996536441
0.0395999995816965	515.374450683594	5.00299978256226	0.000232669233810157
0.0421000004280359	533.258911132813	5.20300006866455	0.00024493713863194
0.0446000012743752	552.665466308594	5.40299987792969	0.000253357866313308
0.0470999984827358	571.706420898438	5.60300016403198	0.000266984949121252
0.0494999985676259	589.435119628906	5.80299997329712	0.000279280618997291
0.0522000009368639	608.450317382813	6.00299978256226	0.00029182099387981
0.054600001021754	625.651123046875	6.20300006866455	0.000302643835311756
0.0570999982301146	642.092224121094	6.40299987792969	0.000318123347824439
0.0596999998379033	661.646850585938	6.60300016403198	0.000322625535773113
0.0620999999227934	675.865234375	6.80299997329712	0.000333562842570245
0.0645999971311539	693.19970703125	7.00299978256226	0.00034814138780348
0.0670000008540228	707.647094726563	7.20300006866455	0.000354580057319254
0.0694999980623834	723.601867675781	7.40299987792969	0.000361398357199505
0.0721999967936426	740.18896484375	7.60300016403198	0.000371457688743249
0.0746000005165115	753.519958496094	7.80299997329712	0.000384803774068132
0.0771999984863214	771.116516113281	8.00300025939941	0.000388475396903232
0.0797000029706396	784.242919921875	8.20300006866455	0.000398435717215762
0.0822000001790002	799.494750976563	8.40299987792969	0.000412666791817173
0.0847999981488101	814.096252441406	8.60299968719482	0.000424132420448586
0.087200001871679	826.638610839844	8.80300045013428	0.000428416387876496
0.0897999998414889	841.932189941406	9.00300025939941	0.000437253154814243
0.0922999970498495	854.859069824219	9.20300006866455	0.000443200144218281
0.0948000015341677	867.831848144531	9.40299987792969	0.000455684057669714
0.0973999995039776	882.145263671875	9.60299968719482	0.000463246455183253
0.0998000032268465	893.840393066406	9.80300045013428	0.000469123915536329
0.102400001196656	907.596618652344	10.0030002593994	0.000475630338769406
0.104899998405017	918.225891113281	10.2030000686646	0.00048379588406533
0.107300002127886	929.561401367188	10.4029998779297	0.000493256433401257
0.109799999336246	940.664855957031	10.6029996871948	0.000502996786963195
0.112200003059115	950.658386230469	10.8030004501343	0.000504772528074682
0.114700000267476	960.834899902344	11.0030002593994	0.000514867482706904
0.117299998237286	971.605224609375	11.2030000686646	0.000523675989825279
0.119700001960155	982.486206054688	11.4029998779297	0.000523624883498996
0.122199999168515	990.854370117188	11.6029996871948	0.000539290951564908
0.124600002891384	998.7490234375	11.8030004501343	0.000537197396624833
0.127000006614253	1005.47155761719	12.0030002593994	0.000547142059076577
0.129499996546656	1012.44281005859	12.2030000686646	0.000548774260096252
0.131900000269525	1018.60412597656	12.4029998779297	0.000562156084924936
0.134500005515292	1028.11669921875	12.6029996871948	0.000567697919905186
0.136999995447695	1034.61364746094	12.8030004501343	0.000570318661630154
0.139399999170564	1042.58447265625	13.0030002593994	0.000579241255763918
0.142100005177781	1051.02575683594	13.2030000686646	0.000578032457269728
0.144499994348735	1056.134765625	13.4029998779297	0.000587795453611761
0.146999998833053	1066.58935546875	13.6029996871948	0.000597571139223874
0.149500003317371	1071.5361328125	13.8030004501343	0.00060312362620607
0.152099994011223	1082.92553710938	14.0030002593994	0.000605609733611345
0.154599998495542	1090.92822265625	14.2030000686646	0.000610771297942847
0.15700000221841	1097.99926757813	14.4029998779297	0.000617696496192366
0.159699993673712	1108.18859863281	14.6029996871948	0.000625863147433847
0.16219999815803	1116.3193359375	14.8030004501343	0.000627095170784742
0.164600001880899	1125.51538085938	15.0030002593994	0.000632369657978415
0.167200007126667	1134.23376464844	15.2030000686646	0.00063824764220044
0.16959999629762	1141.45727539063	15.4029998779297	0.000642489525489509
0.172200001543388	1152.31408691406	15.6029996871948	0.000652579125016928
0.174600005266257	1160.943359375	15.8030004501343	0.000652897055260837
0.17709999519866	1170.29650878906	16.0030002593994	0.000665329454932362
0.179800001205876	1179.916015625	16.2029991149902	0.000670288456603885
0.182100004167296	1187.2041015625	16.4029998779297	0.000672124035190791
0.184699994861148	1197.56091308594	16.6030006408691	0.000678691605571657
0.187099998584017	1206.69177246094	16.80299949646	0.00068130757426843
0.189600003068335	1215.36083984375	17.0030002593994	0.000698714575264603
0.192199993762188	1225.03881835938	17.2029991149902	0.000696658040396869
0.194599997485057	1232.8564453125	17.4029998779297	0.00070502090966329
0.197100001969375	1242.95910644531	17.6030006408691	0.000710025953594595
0.199500005692244	1251.28295898438	17.80299949646	0.000715186644811183
0.201899994863197	1260.13879394531	18.0030002593994	0.000724890211131424
0.204600000870414	1270.44543457031	18.2029991149902	0.000728069222532213
0.207000004593283	1279.27453613281	18.4029998779297	0.000736613234039396
0.209499994525686	1288.8876953125	18.6030006408691	0.000742548611015081
0.212200000532903	1297.62646484375	18.80299949646	0.000745435943827033
0.214600004255772	1307.9697265625	19.0030002593994	0.000747090321965516
0.217199994949624	1316.74133300781	19.2029991149902	0.000757814268581569
0.219699999433942	1324.9208984375	19.4029998779297	0.000763150223065168
0.22220000391826	1335.85693359375	19.6030006408691	0.000769221573136747
0.224699993850663	1344.10974121094	19.80299949646	0.000774500367697328
0.227099997573532	1353.10400390625	20.0030002593994	0.000779642374254763
0.2297000028193	1363.23962402344	20.2029991149902	0.000788869161624461
0.232199992751703	1371.57495117188	20.4029998779297	0.000793343642726541
0.234599996474572	1381.39660644531	20.6030006408691	0.000799386762082577
0.23710000095889	1390.3779296875	20.80299949646	0.000797851011157036
0.239600005443208	1398.59362792969	21.0030002593994	0.000810168799944222
0.24219999613706	1410.18359375	21.2029991149902	0.000812849379144609
0.244599999859929	1417.50390625	21.4029998779297	0.000822879374027252
0.247099989792332	1427.00524902344	21.6030006408691	0.000828968128189445
0.249700009590015	1436.5654296875	21.80299949646	0.000833904778119177
0.252199999522418	1445.38635253906	22.0030002593994	0.00083247059956193
0.254699989454821	1454.79968261719	22.2029991149902	0.000843512243591249
0.257100007729605	1462.4599609375	22.4029998779297	0.000852145720273256
0.259599997662008	1472.28527832031	22.6030006408691	0.000854696030728519
0.26219998835586	1481.68322753906	22.80299949646	0.000864239933434874
0.264600006630644	1490.12609863281	23.0030002593994	0.000867105554789305
0.267199997324497	1499.75085449219	23.2029991149902	0.00087000010535121
0.26959998649545	1507.26916503906	23.4029998779297	0.000872437551151961
0.272100005531684	1517.10473632813	23.6030006408691	0.000884362205397338
0.274599995464087	1526.86865234375	23.80299949646	0.000890626397449523
0.277000013738871	1535.22973632813	24.0030002593994	0.000893417920451611
0.279700005194172	1544.43273925781	24.2029991149902	0.000896573183126748
0.282099994365126	1553.48010253906	24.4029998779297	0.000904262531548738
0.284600013401359	1562.41882324219	24.6030006408691	0.000910627364646643
0.287100003333762	1571.67626953125	24.80299949646	0.000918924575671554
0.289499992504716	1579.35266113281	25.0030002593994	0.000923372397664934
0.292100012302399	1589.67663574219	25.2029991149902	0.000926457112655044
0.294600002234802	1599.32189941406	25.4029998779297	0.000935069285333157
0.296999991405755	1606.4296875	25.6030006408691	0.000940684578381479
0.299500010441989	1616.26306152344	25.80299949646	0.000947611522860825
0.301899999612942	1624.73852539063	26.0030002593994	0.000949622481130064
0.304299988783896	1633.15185546875	26.2029991149902	0.000955628929659724
0.306900008581579	1642.30944824219	26.4029998779297	0.000961756042670459
0.309299997752532	1650.64904785156	26.6030006408691	0.000970032066106796
0.311899988446385	1661.17639160156	26.80299949646	0.000976276292931288
0.314300006721169	1669.0439453125	27.0030002593994	0.000978351105004549
0.316899997415021	1678.28588867188	27.2029991149902	0.000983897596597672
0.319399987347424	1687.9970703125	27.4029998779297	0.00098880787845701
0.321800005622208	1695.85119628906	27.6030006408691	0.0009960065362975
0.32449999707751	1706.28820800781	27.80299949646	0.00100499310065061
0.326999987009913	1714.55688476563	28.0030002593994	0.00100969651248306
0.329400005284697	1724.89013671875	28.2029991149902	0.0010145572014153
0.331999995978549	1734.04541015625	28.4029998779297	0.00102416391018778
0.334300013491884	1742.69470214844	28.6030006408691	0.00102235947269946
0.337000004947186	1753.63830566406	28.80299949646	0.00103285419754684
0.339399994118139	1761.49340820313	29.0030002593994	0.0010407161898911
0.341900013154373	1770.23571777344	29.2029991149902	0.0010441979393363
0.344600004609674	1780.72253417969	29.4029998779297	0.00105449568945915
0.346999993780628	1789.09484863281	29.6030006408691	0.00105478882323951
0.349600013578311	1800.162109375	29.80299949646	0.00106825469993055
0.352100003510714	1808.076171875	30.0030002593994	0.0010697158286348
0.354499992681667	1817.43310546875	30.2029991149902	0.0010758611606434
0.357000011717901	1828.33666992188	30.4029998779297	0.00107900169678032
0.359400000888854	1836.54064941406	30.6030006408691	0.0010871805716306
0.362099992344156	1847.05883789063	30.80299949646	0.00108846812509
0.36450001061894	1855.26586914063	31.0030002593994	0.0010963617824018
0.366899999789894	1864.66088867188	31.2029991149902	0.00110549724195153
0.369399989722297	1875.38208007813	31.4029998779297	0.00111053080763668
0.371800007997081	1884.10961914063	31.6030006408691	0.00111418892629445
0.374399998690933	1893.94287109375	31.80299949646	0.00112089491449296
0.376899988623336	1903.51049804688	32.0029983520508	0.0011302096536383
0.379400007659569	1912.83630371094	32.2029991149902	0.00113456451799721
0.381899997591972	1922.98522949219	32.4029998779297	0.00114402431063354
0.384299986762926	1931.75402832031	32.6030006408691	0.00114951224531978
0.386900006560609	1942.49645996094	32.8030014038086	0.00115471135359257
0.389399996493012	1952.345703125	33.0029983520508	0.00116282631643116
0.391799985663965	1960.92077636719	33.2029991149902	0.00116602797061205
0.394500006223097	1971.77966308594	33.4029998779297	0.00116874126251787
0.3969999961555	1981.42919921875	33.6030006408691	0.00117680686526
0.399499986087903	1991.38720703125	33.8030014038086	0.00118177721742541
0.402100005885586	2000.88220214844	34.0029983520508	0.00118840730283409
0.40449999505654	2009.79772949219	34.2029991149902	0.00119715498294681
0.407000014092773	2020.93823242188	34.4029998779297	0.00120279449038208
0.409500004025176	2030.15905761719	34.6030006408691	0.00120823096949607
0.411999993957579	2040.32629394531	34.8030014038086	0.00121535127982497
0.414500012993813	2050.2001953125	35.0029983520508	0.00122012919746339
0.417000002926216	2059.56567382813	35.2029991149902	0.00122558337170631
0.419499992858618	2070.62548828125	35.4029998779297	0.00123461405746639
0.421900011133403	2079.369140625	35.6030006408691	0.0012481912272051
0.424500001827255	2089.75952148438	35.8030014038086	0.00124764372594655
0.426999991759658	2100.56787109375	36.0029983520508	0.00125529302749783
0.429400010034442	2108.95190429688	36.2029991149902	0.00125781237147748
0.431799999205396	2120.1005859375	36.4029998779297	0.00126516632735729
0.434199988376349	2130.34008789063	36.6030006408691	0.00126335269305855
0.436700007412583	2139.24072265625	36.8030014038086	0.00127455010078847
0.439299998106435	2149.70727539063	37.0029983520508	0.00128528592176735
0.441599986515939	2159.4248046875	37.2029991149902	0.00128741876687855
0.444200006313622	2170.2353515625	37.4029998779297	0.00129796098917723
0.446599995484576	2180.38793945313	37.6030006408691	0.00130241818260401
0.449100014520809	2190.7763671875	37.8030014038086	0.00130583939608186
0.451800005976111	2201.26171875	38.0029983520508	0.00131300103385001
0.454199995147064	2210.64965820313	38.2029991149902	0.00131917279213667
0.456700014183298	2221.75952148438	38.4029998779297	0.0013275200035423
0.459100003354251	2231.56787109375	38.6030006408691	0.00132986006792635
0.461699994048104	2241.626953125	38.8030014038086	0.00133727514185011
0.464200013084337	2253.59741210938	39.0029983520508	0.00134790001902729
0.466600002255291	2262.24633789063	39.2029991149902	0.00135580007918179
0.469099992187694	2273.57543945313	39.4029998779297	0.00135660939849913
0.471700011985376	2284.43334960938	39.6030006408691	0.00136250245850533
0.47410000115633	2294.32495117188	39.8030014038086	0.00137062580324709
0.476699991850182	2305.73071289063	40.0029983520508	0.00137591199018061
0.479100010124967	2315.31567382813	40.2029991149902	0.00138226291164756
0.481600000057369	2326.5341796875	40.4029998779297	0.00138863769825548
0.484199990751222	2337.13208007813	40.6030006408691	0.00140326807741076
0.486600009026006	2346.80810546875	40.8030014038086	0.00140225852373987
0.489300000481308	2358.36962890625	41.0029983520508	0.00140603841282427
0.491700018756092	2368.82250976563	41.2029991149902	0.00142050546128303
0.494199979584664	2378.96606445313	41.4029998779297	0.00142380478791893
0.496599997859448	2390.06420898438	41.6030006408691	0.00142947759013623
0.499000016134232	2399.34497070313	41.8030014038086	0.00143485330045223
0.501699978485703	2412.94067382813	42.0029983520508	0.00144842034205794
0.504199997521937	2421.384765625	42.2029991149902	0.00145336845889688
0.506600015796721	2431.376953125	42.4029998779297	0.00146602047607303
0.509099976625293	2443.59545898438	42.6030006408691	0.00147061422467232
0.511599995661527	2452.21655273438	42.8030014038086	0.00147395546082407
0.51420001545921	2465.64404296875	43.0029983520508	0.00148293294478208
0.516699976287782	2475.48608398438	43.2029991149902	0.00149025348946452
0.519099994562566	2486.07885742188	43.4029998779297	0.00149013544432819
0.521800015121698	2498.29736328125	43.6030006408691	0.00150193809531629
0.524199975188822	2508.16284179688	43.8030014038086	0.00150441669393331
0.526799994986504	2520.41796875	44.0029983520508	0.001516203279607
0.529300014022738	2530.56567382813	44.2029991149902	0.0015194482402876
0.53179997485131	2541.50244140625	44.4029998779297	0.00152688333764672
0.534299993887544	2553.1806640625	44.6030006408691	0.00153136090375483
0.536700012162328	2562.37109375	44.8030014038086	0.00154163572005928
0.539399974513799	2574.23095703125	45.0029983520508	0.00154771469533443
0.541799992788583	2586.1640625	45.2029991149902	0.00154927745461464
0.544200011063367	2596.34252929688	45.4029998779297	0.00156405952293426
0.546899973414838	2608.07446289063	45.6030006408691	0.00157234829384834
0.549299991689622	2618.7998046875	45.8030014038086	0.00158184242900461
0.551900011487305	2631.43798828125	46.0029983520508	0.00158929778262973
0.554299971554428	2642.06713867188	46.2029991149902	0.00159108161460608
0.556899991352111	2652.99926757813	46.4029998779297	0.00159600132610649
0.559400010388345	2665.07958984375	46.6030006408691	0.00160650792531669
0.561800028663129	2675.31005859375	46.8030014038086	0.0016108313575387
0.56439999025315	2687.64794921875	47.0029983520508	0.00162125239148736
0.566800008527935	2696.40649414063	47.2029991149902	0.00163000891916454
0.569300027564168	2709.67358398438	47.4029998779297	0.00163338566198945
0.57189998915419	2721.16430664063	47.6030006408691	0.00163773517124355
0.574200006667525	2732.23828125	47.8030014038086	0.00164436991326511
0.577000027988106	2744.4599609375	48.0029983520508	0.00165194261353463
0.57929998729378	2755.04223632813	48.2029991149902	0.00166333804372698
0.581800006330013	2765.73413085938	48.4029998779297	0.00166524422820657
0.584300025366247	2777.68920898438	48.6030006408691	0.00167483184486628
0.586599984671921	2787.38061523438	48.8030014038086	0.00168599758762866
0.589100003708154	2799.7890625	49.0029983520508	0.0016906603705138
0.591500021982938	2810.21020507813	49.2029991149902	0.00169612269382924
0.593899982050061	2821.56079101563	49.4029998779297	0.00170028174761683
0.596500001847744	2833.45874023438	49.6030006408691	0.00171342131216079
0.598900020122528	2843.90014648438	49.8030014038086	0.00172149832360446
0.601399980951101	2856.83032226563	50.0029983520508	0.00172592455055565
0.603799999225885	2867.048828125	50.2029991149902	0.00173088861629367
0.606300018262118	2878.97045898438	50.4029998779297	0.00174234004225582
0.60889997985214	2892.04614257813	50.6030006408691	0.00174956570845097
0.611399998888373	2903.373046875	50.8030014038086	0.00175605283584446
0.613900017924607	2915.06982421875	51.0029983520508	0.0017672999529168
0.616399978753179	2926.70825195313	51.2029991149902	0.00177165924105793
0.618999998550862	2937.97924804688	51.4029998779297	0.00177796452771872
0.621500017587095	2950.68725585938	51.6030006408691	0.00178587436676025
0.623899977654219	2960.71801757813	51.8030014038086	0.00179465289693326
0.626499997451901	2972.79418945313	52.0029983520508	0.00180520582944155
0.629000016488135	2984.95361328125	52.2029991149902	0.00180662015918642
0.631399976555258	2995.99975585938	52.4029998779297	0.0018098532455042
0.633899995591491	3008.51684570313	52.6030006408691	0.00182296615093946
0.636400014627725	3020.318359375	52.8030014038086	0.00183062057476491
0.638899975456297	3032.12548828125	53.0029983520508	0.0018427746836096
0.641399994492531	3045.04467773438	53.2029991149902	0.00184887181967497
0.643900013528764	3054.93041992188	53.4029998779297	0.00185043190140277
0.646499975118786	3068.275390625	53.6030006408691	0.00185800564941019
0.64899999415502	3080.19165039063	53.8030014038086	0.00186854915227741
0.651400012429804	3091.53979492188	54.0029983520508	0.0018750480376184
0.653999974019825	3103.77001953125	54.2029991149902	0.00188169057946652
0.656499993056059	3114.70581054688	54.4029998779297	0.00189444317948073
0.659000012092292	3127.90747070313	54.6030006408691	0.00190695479977876
0.661499972920865	3139.01708984375	54.8030014038086	0.00191109778825194
0.664099992718548	3152.10205078125	55.0029983520508	0.00191441120114177
0.666600011754781	3164.1318359375	55.2029991149902	0.00192366586998105
0.668999971821904	3174.80493164063	55.4029998779297	0.00193343008868396
0.671499990858138	3187.62036132813	55.6030006408691	0.00193484651390463
0.674000009894371	3198.51098632813	55.8030014038086	0.00194741622544825
0.676500028930604	3211.51342773438	56.0029983520508	0.00195157760754228
0.679099990520626	3224.63500976563	56.2029991149902	0.00196076743304729
0.681400008033961	3235.17041015625	56.4029998779297	0.00197011209093034
0.684100028593093	3248.30639648438	56.6030006408691	0.00197565462440252
0.686499988660216	3259.49584960938	56.8030014038086	0.00198458041995764
0.68900000769645	3272.16064453125	57.0029983520508	0.00199567107483745
0.691500026732683	3284.4091796875	57.2029991149902	0.00200544763356447
0.693799986038357	3294.89770507813	57.4029998779297	0.00200833682902157
0.696500006597489	3308.98559570313	57.6030006408691	0.00201760395430028
0.698900024872273	3319.86596679688	57.8030014038086	0.00202397396788001
0.701399985700846	3332.5380859375	58.0029983520508	0.00202982290647924
0.703900004737079	3344.95556640625	58.2029991149902	0.00204362580552697
0.706300023011863	3355.87646484375	58.4029998779297	0.00205339724197984
0.708999985363334	3370.57861328125	58.6030006408691	0.00205881963483989
0.711400003638119	3381.18359375	58.8030014038086	0.00206434307619929
0.713900022674352	3393.73999023438	59.0029983520508	0.0020727280061692
0.716599985025823	3407.0341796875	59.2029991149902	0.00208398536778986
0.719000003300607	3417.47241210938	59.4029998779297	0.00209091091528535
0.72160002309829	3431.736328125	59.6030006408691	0.00209642737172544
0.723999983165413	3442.75390625	59.8030014038086	0.00210845377296209
0.726500002201647	3454.96533203125	60.0029983520508	0.00211379653774202
0.72900002123788	3468.51806640625	60.2029991149902	0.00212516868487
0.731399981305003	3478.796875	60.4029998779297	0.00213030423037708
0.734000001102686	3493.50024414063	60.6030006408691	0.00213639577850699
0.73640001937747	3504.03784179688	60.8030014038086	0.00214536325074732
0.738899980206043	3515.93725585938	61.0029983520508	0.00215624668635428
0.741399999242276	3529.53930664063	61.2029991149902	0.00217169662937522
0.74380001751706	3540.16284179688	61.4029998779297	0.00217574858106673
0.746499979868531	3554.33740234375	61.6030006408691	0.0021886311005801
0.748899998143315	3565.17407226563	61.8030014038086	0.00219285464845598
0.751400017179549	3577.7138671875	62.0029983520508	0.00220398092642426
0.753899978008121	3591.23461914063	62.2029991149902	0.00221639452502131
0.756299996282905	3602.11987304688	62.4029998779297	0.0022246316075325
0.759000016842037	3615.70190429688	62.6030006408691	0.00223017996177077
0.761399976909161	3627.6357421875	62.8030014038086	0.00224391231313348
0.763799995183945	3639.4580078125	63.0029983520508	0.00224896380677819
0.766500015743077	3651.99096679688	63.2029991149902	0.00226466590538621
0.768999976571649	3663.23779296875	63.4029998779297	0.00227083917707205
0.771499995607883	3676.83935546875	63.6030006408691	0.0022838213481009
0.773900013882667	3687.90966796875	63.8030014038086	0.0022938100155443
0.776499975472689	3700.35083007813	64.0029983520508	0.00230291043408215
0.778999994508922	3712.5078125	64.2030029296875	0.00231776433065534
0.781500013545156	3724.3046875	64.4029998779297	0.00232997606508434
0.783999974373728	3735.8359375	64.6029968261719	0.00234084785915911
0.786499993409961	3746.90087890625	64.8030014038086	0.0023475643247366
0.788900011684746	3758.75927734375	65.0029983520508	0.00235911901108921
0.791399972513318	3772.6640625	65.2030029296875	0.0023708064109087
0.793799990788102	3783.35620117188	65.4029998779297	0.00237884907983243
0.796300009824336	3794.28198242188	65.6029968261719	0.00238815019838512
0.798800028860569	3806.50366210938	65.8030014038086	0.00240571401081979
0.801099988166243	3816.60327148438	66.0029983520508	0.00241572433151305
0.803700007963926	3829.634765625	66.2030029296875	0.00242741941474378
0.80610002623871	3840.82421875	66.4029998779297	0.00244389264844358
0.808599987067282	3850.75415039063	66.6029968261719	0.00245660031214356
0.811100006103516	3863.82446289063	66.8030014038086	0.00246911495923996
0.8135000243783	3873.80200195313	67.0029983520508	0.00248430366627872
0.816199986729771	3886.5888671875	67.2030029296875	0.00248952559195459
0.818600005004555	3897.75122070313	67.4029998779297	0.00250442954711616
0.821000023279339	3907.62377929688	67.6029968261719	0.00252153701148927
0.82369998563081	3920.99780273438	67.8030014038086	0.00253282301127911
0.826100003905594	3930.40161132813	68.0029983520508	0.00254896492697299
0.828700023703277	3943.21728515625	68.2030029296875	0.00256433407776058
0.8310999837704	3952.72583007813	68.4029998779297	0.00257367314770818
0.833700003568083	3964.21313476563	68.6029968261719	0.00259483978152275
0.836200022604316	3976.16040039063	68.8030014038086	0.00260934326797724
0.83859998267144	3984.58349609375	69.0029983520508	0.00262982561253011
0.841400003992021	3996.58715820313	69.2030029296875	0.00264975288882852
0.843800022266805	4007.14404296875	69.4029998779297	0.00266653043217957
0.846299983095378	4017.50244140625	69.6029968261719	0.00268011447042227
0.84890000289306	4028.2470703125	69.8030014038086	0.00270124920643866
0.851300021167845	4036.6630859375	70.0029983520508	0.00271751708351076
0.853899982757866	4048.12524414063	70.2030029296875	0.00273590674623847
0.85630000103265	4056.84106445313	70.4029998779297	0.00275340839289129
0.858900020830333	4067.01123046875	70.6029968261719	0.00277715059928596
0.861399981658906	4076.57983398438	70.8030014038086	0.00279570603743196
0.86379999993369	4086.47631835938	71.0029983520508	0.00281542306765914
0.866500020492822	4096.564453125	71.2030029296875	0.00284051150083542
0.868899980559945	4104.73291015625	71.4029998779297	0.00285724480636418
0.871399999596179	4112.86669921875	71.6029968261719	0.00288257887586951
0.873900018632412	4123.42333984375	71.8030014038086	0.00290972692891955
0.876299978699535	4130.83056640625	72.0029983520508	0.00293076317757368
0.878999999258667	4141.14990234375	72.2030029296875	0.00295109860599041
0.881400017533451	4148.46826171875	72.4029998779297	0.00297838379628956
0.883799977600574	4156.931640625	72.6029968261719	0.00299743795767426
0.886399997398257	4165.462890625	72.8030014038086	0.00302926008589566
0.888700014911592	4172.712890625	73.0029983520508	0.00304791843518615
0.891399977263063	4182.1298828125	73.2030029296875	0.00307423202320933
0.893699994776398	4187.8798828125	73.4029998779297	0.00309775327332318
0.896100013051182	4195.94775390625	73.6029968261719	0.00312704360112548
0.898699974641204	4204.76171875	73.8030014038086	0.00315063260495663
0.901099992915988	4211.75830078125	74.0029983520508	0.00318214879371226
0.903700012713671	4219.5439453125	74.2030029296875	0.00321089290082455
0.906099972780794	4226.91015625	74.4029998779297	0.00323685817420483
0.908599991817027	4233.88671875	74.6029968261719	0.00327144097536802
0.91120001161471	4241.40625	74.8030014038086	0.00329814362339675
0.913699972443283	4248.708984375	75.0029983520508	0.0033281680662185
0.916199991479516	4254.03955078125	75.2030029296875	0.00335931428708136
0.9186000097543	4261.41943359375	75.4029998779297	0.00339237856678665
0.921100028790534	4266.3310546875	75.6029968261719	0.00342196482233703
0.923699990380555	4275.1240234375	75.8030014038086	0.00345366122201085
0.926200009416789	4280.2861328125	76.0029983520508	0.00348529941402376
0.928600027691573	4286.591796875	76.2030029296875	0.00351981725543737
0.931099988520145	4292.8544921875	76.4029998779297	0.00355393718928099
0.93350000679493	4297.13623046875	76.6029968261719	0.00358123169280589
0.936200027354062	4304.74853515625	76.8030014038086	0.00361882080323994
0.938599987421185	4310.14013671875	77.0029983520508	0.00364989973604679
0.941100006457418	4316.41259765625	77.2030029296875	0.00368953542783856
0.943600025493652	4321.85546875	77.4029998779297	0.00372141902334988
0.946099986322224	4327.31103515625	77.6029968261719	0.00375699414871633
0.948600005358458	4333.24951171875	77.8030014038086	0.00379519909620285
0.951100024394691	4337.78466796875	78.0029983520508	0.00382893835194409
0.953499984461814	4342.177734375	78.2030029296875	0.00386246456764638
0.956100004259497	4348.67431640625	78.4029998779297	0.00390035635791719
0.95860002329573	4352.23583984375	78.6029968261719	0.00393338222056627
0.961099984124303	4359.7763671875	78.8030014038086	0.00397177040576935
0.963500002399087	4363.5771484375	79.0029983520508	0.00400901911780238
0.96610002219677	4368.48046875	79.2030029296875	0.00404760940000415
0.968599983025342	4374.380859375	79.4029998779297	0.00408199289813638
0.971100002061576	4377.953125	79.6029968261719	0.00411964068189263
0.973800022620708	4384.494140625	79.8030014038086	0.00416281074285507
0.976199982687831	4386.9990234375	80.0029983520508	0.0041996669024229
0.978600000962615	4392.0546875	80.2030029296875	0.00423882389441133
0.981200020760298	4397.29150390625	80.4029998779297	0.00428106542676687
0.983600039035082	4399.52197265625	80.6029968261719	0.0043204678222537
0.986299943178892	4406.3388671875	80.8030014038086	0.00435857474803925
0.988699961453676	4408.65869140625	81.0029983520508	0.00439882092177868
0.99109997972846	4413.0810546875	81.2030029296875	0.004439493175596
0.993800000287592	4418.4873046875	81.4029998779297	0.00447949860244989
0.996200018562376	4421.40283203125	81.6029968261719	0.00451935175806284
0.998900039121509	4426.9794921875	81.8030014038086	0.00456440215930343
1.00130005739629	4428.63671875	82.0029983520508	0.00460329279303551
1.00369995925575	4433.01171875	82.2030029296875	0.00464370846748352
1.00619997829199	4438.86376953125	82.4029998779297	0.00468076672405005
1.00859999656677	4440.39697265625	82.6029968261719	0.00472375378012657
1.0113000171259	4446.52197265625	82.8030014038086	0.00476572941988707
1.01370003540069	4449.150390625	83.0029983520508	0.00479974551126361
1.01620005443692	4452.49365234375	83.2030029296875	0.00484449416399002
1.01869995705783	4457.357421875	83.4029998779297	0.0048852413892746
1.02109997533262	4459.4287109375	83.6029968261719	0.00492558069527149
1.02379999589175	4465.28076171875	83.8030014038086	0.00496596191078424
1.02610001340508	4465.6552734375	84.0029983520508	0.00500993756577373
1.02850003167987	4469.3115234375	84.2030029296875	0.0050532310269773
1.031200052239	4475.2392578125	84.4029998779297	0.00509425438940525
1.03369995485991	4478.173828125	84.6029968261719	0.00513888476416469
1.0362999746576	4482.55615234375	84.8030014038086	0.00518391560763121
1.03879999369383	4484.16357421875	85.0029983520508	0.0052293767221272
1.04130001273006	4487.4755859375	85.2030029296875	0.00526780355721712
1.04390003252774	4492.00439453125	85.4029998779297	0.00531247956678271
1.04630005080253	4494.1689453125	85.6029968261719	0.00535311689600348
1.04889995418489	4498.173828125	85.8030014038086	0.00539555912837386
1.05119997169822	4500.27685546875	86.0029983520508	0.0054419944062829
1.05369999073446	4503.49755859375	86.2030029296875	0.00548255350440741
1.05620000977069	4508.22802734375	86.4029998779297	0.00552894826978445
1.05860002804548	4510.9189453125	86.6029968261719	0.00556939234957099
1.06110004708171	4514.3818359375	86.8030014038086	0.00561383366584778
1.06349994894117	4516.30615234375	87.0029983520508	0.00565336924046278
1.0659999679774	4519.5361328125	87.2030029296875	0.00570013606920838
1.06859998777509	4523.43505859375	87.4029998779297	0.00574172241613269
1.07100000604987	4525.939453125	87.6029968261719	0.00578354392200708
1.07340002432466	4528.947265625	87.8030014038086	0.00582801084965467
1.07600004412234	4532.1005859375	88.0029983520508	0.00587310083210468
1.07849994674325	4534.64111328125	88.2030029296875	0.00591436168178916
1.08099996577948	4538.458984375	88.4029998779297	0.00596169847995043
1.08359998557717	4540.6689453125	88.6029968261719	0.00600507296621799
1.0861000046134	4543.17041015625	88.8030014038086	0.00605342909693718
1.08860002364963	4546.1220703125	89.0029983520508	0.00610168045386672
1.09110004268587	4547.88134765625	89.2030029296875	0.00613946095108986
1.09369994606823	4552.57958984375	89.4029998779297	0.00618994794785976
1.09619996510446	4554.052734375	89.6029968261719	0.00623358692973852
1.09859998337924	4557.11279296875	89.8030014038086	0.00628002919256687
1.10120000317693	4560.64990234375	90.0029983520508	0.00632071262225509
1.10360002145171	4562.38916015625	90.2030029296875	0.00636233389377594
1.10620004124939	4567.26953125	90.4029998779297	0.00640670862048864
1.10859994310886	4568.31982421875	90.6029968261719	0.00645007006824017
1.11109996214509	4571.7626953125	90.8030014038086	0.00649838848039508
1.11369998194277	4574.2236328125	91.0029983520508	0.00654128286987543
1.11610000021756	4575.35546875	91.2030029296875	0.00657842354848981
1.11870002001524	4580.3759765625	91.4029998779297	0.00662693008780479
1.12110003829002	4582.0439453125	91.6029968261719	0.00667187431827188
1.12370005808771	4584.83642578125	91.8030014038086	0.00671871192753315
1.12619996070862	4588.37939453125	92.0029983520508	0.00676060933619738
1.1285999789834	4588.830078125	92.2030029296875	0.00680512096732855
1.13129999954253	4592.9619140625	92.4029998779297	0.00685170432552695
1.13370001781732	4594.6982421875	92.6029968261719	0.00689072115346789
1.13620003685355	4597.146484375	92.8030014038086	0.00694112293422222
1.13880005665123	4600.3544921875	93.0029983520508	0.00698329787701368
1.14129995927215	4601.2451171875	93.2030029296875	0.00702841999009252
1.14389997906983	4605.7021484375	93.4029998779297	0.00707048829644918
1.14629999734461	4606.47900390625	93.6029968261719	0.00711710890755057
1.1489000171423	4609.16845703125	93.8030014038086	0.00716579658910632
1.15140003617853	4612.736328125	94.0029983520508	0.00720556685701013
1.15380005445331	4614.15771484375	94.2030029296875	0.00725175999104977
1.15649995859712	4617.50537109375	94.4029998779297	0.00729416776448488
1.15899997763336	4619.291015625	94.6029968261719	0.00734207220375538
1.16139999590814	4621.71630859375	94.8030014038086	0.00738895963877439
1.16400001570582	4624.8544921875	95.0029983520508	0.00743241794407368
1.16650003474206	4625.9228515625	95.2030029296875	0.00747780129313469
1.16900005377829	4629.59228515625	95.4029998779297	0.00751735363155603
1.17139995563775	4631.95703125	95.6029968261719	0.00756356073543429
1.17389997467399	4633.71044921875	95.8030014038086	0.0076069924980402
1.17649999447167	4636.55126953125	96.0029983520508	0.00765864085406065
1.17890001274645	4638.5458984375	96.2030029296875	0.00770024210214615
1.18130003102124	4640.61962890625	96.4029998779297	0.00774226756766438
1.18380005005747	4643.326171875	96.6029968261719	0.00778899341821671
1.18609995115548	4644.44384765625	96.8030014038086	0.00782935973256826
1.18859997019172	4648.00146484375	97.0029983520508	0.00788107700645924
1.1909999884665	4649.01953125	97.2030029296875	0.00791680905967951
1.19340000674129	4652.35791015625	97.4029998779297	0.00796171557158232
1.19590002577752	4654.98388671875	97.6029968261719	0.00800978019833565
1.1983000440523	4657.3271484375	97.8030014038086	0.00805254187434912
1.20079994667321	4659.78125	98.0029983520508	0.00810370687395334
1.203199964948	4661.1337890625	98.2030029296875	0.00814235117286444
1.20579998474568	4663.75830078125	98.4029998779297	0.00819029565900564
1.20830000378191	4667.31103515625	98.6029968261719	0.00823620613664389
1.21080002281815	4668.3603515625	98.8030014038086	0.00828313082456589
1.21330004185438	4670.50341796875	99.0029983520508	0.00833115540444851
1.21579994447529	4671.85888671875	99.2030029296875	0.00837777275592089
1.21829996351153	4674.20947265625	99.4029998779297	0.00842071790248156
1.22089998330921	4676.875	99.6029968261719	0.00847367197275162
1.22340000234544	4678.48388671875	99.8030014038086	0.00851893424987793
1.22590002138168	4680.46826171875	100.002998352051	0.00856484286487103
1.22840004041791	4681.77001953125	100.203002929688	0.00861367955803871
1.23089994303882	4683.90283203125	100.40299987793	0.00865844823420048
1.2334999628365	4687.291015625	100.602996826172	0.00870357546955347
1.23589998111129	4687.453125	100.803001403809	0.00875198747962713
1.23850000090897	4690.90625	101.002998352051	0.00879856012761593
1.2410000199452	4693.49560546875	101.203002929688	0.00883641932159662
1.24340003821999	4696.15576171875	101.40299987793	0.0088872779160738
1.2460999423638	4699.06103515625	101.602996826172	0.00893207918852568
1.24859996140003	4699.47021484375	101.803001403809	0.00897977966815233
1.25099997967482	4701.44091796875	102.002998352051	0.00902426149696112
1.25349999871105	4704.1494140625	102.203002929688	0.00907023716717958
1.25590001698583	4704.88427734375	102.40299987793	0.00910196453332901
1.25860003754497	4709.2294921875	102.602996826172	0.0091527821496129
1.26100005581975	4709.244140625	102.803001403809	0.00919296499341726
1.26339995767921	4711.65380859375	103.002998352051	0.00923565123230219
1.26609997823834	4715.1083984375	103.203002929688	0.00928084552288055
1.26849999651313	4715.9033203125	103.40299987793	0.00932043045759201
1.27110001631081	4720.53662109375	103.602996826172	0.00936491042375565
1.27360003534704	4720.5908203125	103.803001403809	0.00940706487745047
1.27610005438328	4722.8154296875	104.002998352051	0.00945220794528723
1.27869995776564	4725.26318359375	104.203002929688	0.00948602054268122
1.28109997604042	4725.85400390625	104.40299987793	0.00952725671231747
1.28379999659956	4729.5712890625	104.602996826172	0.00956907402724028
1.28620001487434	4730.453125	104.803001403809	0.00960912462323904
1.28870003391057	4732.4853515625	105.002998352051	0.00964160170406103
1.29130005370826	4734.6103515625	105.203002929688	0.0096836406737566
1.29369995556772	4734.6865234375	105.40299987793	0.00971980113536119
1.2962999753654	4738.7880859375	105.602996826172	0.00975634064525366
1.29869999364018	4738.27490234375	105.803001403809	0.00979203544557095
1.30110001191497	4740.6416015625	106.002998352051	0.00982324592769146
1.3038000324741	4743.67431640625	106.203002929688	0.00985766854137182
1.30620005074888	4745.28466796875	106.40299987793	0.00989004503935575
1.3086999533698	4748.435546875	106.602996826172	0.00992735661566257
1.31109997164458	4748.89404296875	106.803001403809	0.00995874125510454
1.31359999068081	4751.4248046875	107.002998352051	0.00999289937317371
1.3162000104785	4754.89013671875	107.203002929688	0.0100318482145667
1.31860002875328	4756.45556640625	107.40299987793	0.0100596565753222
1.32100004702806	4758.80615234375	107.602996826172	0.0100882323458791
1.32339994888753	4761.40576171875	107.803001403809	0.0101288137957454
1.32579996716231	4763.3251953125	108.002998352051	0.0101587399840355
1.32839998695999	4765.86767578125	108.203002929688	0.0101993307471275
1.33090000599623	4768.01416015625	108.40299987793	0.0102351596578956
1.33340002503246	4769.7421875	108.602996826172	0.010273122228682
1.33590004406869	4773.0439453125	108.803001403809	0.0103096514940262
1.33829994592816	4773.61865234375	109.002998352051	0.01034174580127
1.34099996648729	4776.3828125	109.203002929688	0.0103898625820875
1.34349998552352	4777.58203125	109.40299987793	0.0104289995506406
1.34600000455976	4778.4404296875	109.602996826172	0.0104643926024437
1.34850002359599	4779.64013671875	109.803001403809	0.0105116171762347
1.35100004263222	4780.08203125	110.002998352051	0.0105565721169114
1.35349994525313	4782.5439453125	110.203002929688	0.0106036141514778
1.35599996428937	4784.00732421875	110.40299987793	0.0106507353484631
1.3584999833256	4785.6005859375	110.602996826172	0.0106989573687315
1.36100000236183	4786.79443359375	110.803001403809	0.0107504548504949
1.36350002139807	4787.84814453125	111.002998352051	0.0107988966628909
1.3662000419572	4791.58203125	111.203002929688	0.0108595853671432
1.36859994381666	4791.19287109375	111.40299987793	0.0109160719439387
1.3710999628529	4793.32568359375	111.602996826172	0.0109749836847186
1.37369998265058	4794.53369140625	111.803001403809	0.0110336048528552
1.37610000092536	4793.80126953125	112.002998352051	0.0110927345231175
1.37870002072304	4797.12060546875	112.203002929688	0.0111601240932941
1.38110003899783	4797.77294921875	112.40299987793	0.0112237222492695
1.38360005803406	4799.5654296875	112.602996826172	0.0112887984141707
1.38619996141642	4801.4638671875	112.803001403809	0.0113583654165268
1.38849997892976	4802.49169921875	113.002998352051	0.011419054120779
1.39109999872744	4805.8388671875	113.203002929688	0.0114886332303286
1.39340001624078	4806.1435546875	113.40299987793	0.0115542514249682
[...]
4.71499981358647	5866.779296875	259.35400390625	0.067997582256794
4.72499988973141	5955.13623046875	259.753997802734	0.0681433379650116
4.73529985174537	5850.8974609375	260.153991699219	0.0688069686293602
4.74510015919805	5945.177734375	260.553985595703	0.0689377784729004
4.75540012121201	5833.50390625	260.954010009766	0.0696106925606728
4.7651999630034	5935.02392578125	261.35400390625	0.0697242692112923
4.77499980479479	5886.1201171875	261.753997802734	0.0700368136167526
4.7846999950707	5923.59716796875	262.153991699219	0.0702997669577599
4.79470007121563	5848.2109375	262.553985595703	0.0708829164505005
4.80479979887605	5949.64501953125	262.954010009766	0.0710046514868736
4.8147002235055	5837.65869140625	263.35400390625	0.071670301258564
4.82500018551946	5945.13818359375	263.753997802734	0.0717865005135536
4.83490014448762	5920.20654296875	264.153991699219	0.0718379318714142
4.84480010345578	5995.7060546875	264.553985595703	0.071932889521122
4.85499994829297	5837.60205078125	264.954010009766	0.0726126953959465
4.8650000244379	5941.796875	265.35400390625	0.0727151408791542
4.87510021775961	5862.31689453125	265.753997802734	0.0730925500392914
4.88509982824326	5914.94873046875	266.153991699219	0.0732932910323143
4.89499978721142	6010.66064453125	266.553985595703	0.0733999460935593
4.90499986335635	5889.6640625	266.954010009766	0.0737366676330566
4.91480017080903	5987.53173828125	267.35400390625	0.0738382041454315
4.92489989846945	5995.6123046875	267.753997802734	0.0738756358623505
4.93479985743761	5998.94873046875	268.153991699219	0.0739580318331718
4.94500016793609	5910.57275390625	268.553985595703	0.0742447003722191
4.95499977841973	6006.119140625	268.954010009766	0.0743489488959312
4.96499985456467	5879.62890625	269.35400390625	0.0745588093996048
4.9749999307096	5981.345703125	269.753997802734	0.0746553838253021
4.98489988967776	5843.4609375	270.153991699219	0.0746166482567787
4.99500008299947	5950.55322265625	270.553985595703	0.0747105479240417
5.0050001591444	5980.61279296875	270.954010009766	0.0747552961111069
5.01499976962805	5927.18017578125	271.35400390625	0.0747129246592522
5.02499984577298	6018.9501953125	271.753997802734	0.074799008667469
5.03499992191792	5901.72216796875	272.153991699219	0.074742928147316
5.04510011523962	6004.052734375	272.553985595703	0.0748236253857613
5.05500007420778	5990.939453125	272.954010009766	0.0750779956579208
5.0650998018682	5995.5498046875	273.35400390625	0.075264111161232
5.07500022649765	6011.8671875	273.753997802734	0.0754567235708237
5.0849998369813	5899.36865234375	274.153991699219	0.0754590034484863
5.09499991312623	5995.10400390625	274.553985595703	0.0755533203482628
5.10489987209439	6017.20947265625	274.954010009766	0.0756280124187469
5.1150000654161	5983.419921875	275.35400390625	0.0760700479149818
5.12500014156103	5948.29296875	275.753997802734	0.0765255019068718
5.13509986922145	5982.638671875	276.153991699219	0.0768261551856995
5.14499982818961	6042.99169921875	276.553985595703	0.0770197063684464
5.15499990433455	5920.88623046875	276.954010009766	0.0777194425463676
5.16499998047948	6018.31201171875	277.35400390625	0.0778516307473183
5.17500005662441	5883.6171875	277.753997802734	0.078573077917099
5.18509978428483	5986.96875	278.153991699219	0.078686311841011
5.19509986042976	5869.5107421875	278.553985595703	0.0793635323643684
5.2050999365747	5972.38232421875	278.954010009766	0.0794669315218925
5.21510001271963	6050.404296875	279.35400390625	0.0796349048614502
5.22499997168779	5941.63134765625	279.753997802734	0.0802856609225273
5.23500004783273	6040.712890625	280.153991699219	0.0804027393460274
5.24490000680089	5915.39453125	280.553985595703	0.0809990838170052
5.25500020012259	6019.5615234375	280.954010009766	0.0810946226119995
5.26490015909076	5888.72900390625	281.35400390625	0.0813359767198563
5.27480011805892	5992.37255859375	281.753997802734	0.0814402177929878
5.28489984571934	6002.9306640625	282.153991699219	0.0814719647169113
5.29489992186427	6038.3193359375	282.553985595703	0.0815175920724869
5.30500011518598	5941.29736328125	282.954010009766	0.0814680680632591
5.31500019133091	6037.3134765625	283.35400390625	0.0815486535429955
5.32499980181456	5906.646484375	283.753997802734	0.0814575627446175
5.33509999513626	6009.17236328125	284.153991699219	0.081538587808609
5.34510007128119	5879.1884765625	284.553985595703	0.0814487263560295
5.35529991611838	5985.10986328125	284.954010009766	0.0815235078334808
5.36510022357106	6067.0927734375	285.35400390625	0.0815948992967606
5.37500018253922	5955.1064453125	285.753997802734	0.0815403833985329
5.38469990715384	6051.162109375	286.153991699219	0.0816149562597275
5.39480010047555	5988.28662109375	286.553985595703	0.082040086388588
5.40499994531274	5888.5185546875	286.954010009766	0.0826656669378281
5.4148999042809	5971.2685546875	287.35400390625	0.0828322321176529
5.42500009760261	6047.4052734375	287.753997802734	0.0830023735761642
5.43500017374754	5940.015625	288.153991699219	0.0836666524410248
5.44499978423119	6038.6103515625	288.553985595703	0.0837930366396904
5.45499986037612	5911.6142578125	288.954010009766	0.0844930410385132
5.46499993652105	6015.005859375	289.35400390625	0.0846018642187119
5.47500001266599	5884.49169921875	289.753997802734	0.0853221341967583
5.48479985445738	5985.615234375	290.153991699219	0.0854258015751839
5.49509981647134	5854.82568359375	290.553985595703	0.0861344933509827
5.5049997754395	5954.41845703125	290.954010009766	0.0862649083137512
5.51499985158443	6045.25146484375	291.35400390625	0.0864071100950241
5.52520016208291	5935.453125	291.753997802734	0.0870811566710472
5.5350000038743	6033.494140625	292.153991699219	0.0871974900364876
5.54510019719601	5921.5439453125	292.553985595703	0.0877136513590813
5.55509980767965	6009.69384765625	292.954010009766	0.0878694802522659
5.56520000100136	5875.07080078125	293.35400390625	0.088588111102581
5.57530019432306	5979.173828125	293.753997802734	0.0887106582522392
5.58499991893768	6069.85302734375	294.153991699219	0.088837094604969
5.59489987790585	5942.03466796875	294.553985595703	0.0895259529352188
5.60460006818175	6042.41845703125	294.954010009766	0.0896366983652115
5.61479991301894	5909.13134765625	295.35400390625	0.090278334915638
5.62490010634065	6010.93017578125	295.753997802734	0.0903990641236305
5.63499983400106	6096.81005859375	296.153991699219	0.0905135422945023
5.64520014449954	5973.68603515625	296.553985595703	0.0909520089626312
5.65499998629093	6070.1552734375	296.954010009766	0.0910655111074448
5.66529994830489	5941.03515625	297.35400390625	0.0914378315210342
5.6750001385808	6041.17138671875	297.753997802734	0.091543547809124
5.68500021472573	5905.28564453125	298.153991699219	0.0919303372502327
5.6949001736939	6004.001953125	298.553985595703	0.0920373275876045
5.70489978417754	6094.35205078125	298.954010009766	0.0921549424529076
5.71499997749925	5971.79638671875	299.35400390625	0.0924792140722275
5.72479981929064	6069.2666015625	299.753997802734	0.0925892293453217
5.73500012978911	5942.49169921875	300.153991699219	0.0927075818181038
5.74490008875728	6042.40869140625	300.553985595703	0.0928167253732681
5.75490016490221	6041.39990234375	300.954010009766	0.0930042937397957
5.76499989256263	6059.64794921875	301.35400390625	0.0931509956717491
5.77489985153079	5936.6337890625	301.753997802734	0.0930874049663544
5.7850000448525	6035.98095703125	302.153991699219	0.093168243765831
5.79500012099743	5916.2353515625	302.553985595703	0.0930935814976692
5.80500019714236	6001.72509765625	302.954010009766	0.0931668132543564
5.81480003893375	6086.09619140625	303.35400390625	0.0932449623942375
5.82510000094771	5947.18310546875	303.753997802734	0.0931506529450417
5.83510007709265	6046.9755859375	304.153991699219	0.0932323113083839
5.84500003606081	6031.16064453125	304.553985595703	0.0932305604219437
5.85500011220574	6000.26025390625	304.954010009766	0.0932124778628349
5.86479995399714	6094.0419921875	305.35400390625	0.093289814889431
5.87499979883432	5984.03125	305.753997802734	0.0932152271270752
5.88509999215603	6086.4765625	306.153991699219	0.0932984799146652
5.89499995112419	6015.923828125	306.553985595703	0.0932545438408852
5.90500002726912	6045.75927734375	306.954010009766	0.0932867750525475
5.91500010341406	5971.69775390625	307.35400390625	0.0932398661971092
5.92509983107448	6070.1533203125	307.753997802734	0.0933141112327576
5.93520002439618	5927.01953125	308.153991699219	0.0932152643799782
5.94530021771789	6027.00244140625	308.553985595703	0.093294769525528
5.9553999453783	6111.9365234375	308.954010009766	0.0933685526251793
5.96529990434647	5984.8525390625	309.35400390625	0.0932759791612625
5.97500009462237	6080.259765625	309.753997802734	0.093354232609272
5.98469981923699	5942.89892578125	310.153991699219	0.0932589322328568
5.99469989538193	6044.32958984375	310.553985595703	0.0933434143662453
6.00469997152686	6121.8564453125	310.954010009766	0.0934280380606651
6.01480016484857	6021.919921875	311.35400390625	0.09336306899786
6.02500000968575	6119.98876953125	311.753997802734	0.0934509858489037
6.03479985147715	6048.68408203125	312.153991699219	0.0938958674669266
6.04490004479885	6099.576171875	312.553985595703	0.0941246002912521
6.05490012094378	5998.32861328125	312.954010009766	0.094807356595993
6.0649998486042	6094.673828125	313.35400390625	0.0949372723698616
6.07520015910268	5961.51123046875	313.753997802734	0.0956991240382195
6.08510011807084	6061.53857421875	314.153991699219	0.0958215743303299
6.09510019421577	5934.46923828125	314.553985595703	0.0965548604726791
6.10490003600717	6018.0302734375	314.954010009766	0.0967279747128487
6.11469987779856	6110.59423828125	315.35400390625	0.096854954957962
6.12469995394349	5976.36865234375	315.753997802734	0.097621276974678
6.1348001472652	6077.1435546875	316.153991699219	0.0977490022778511
6.14499999210238	5944.2529296875	316.553985595703	0.0985168591141701
6.15500006824732	6046.30859375	316.954010009766	0.0986437052488327
6.16509979590774	5932.19677734375	317.35400390625	0.0993476212024689
6.17500022053719	6019.54248046875	317.753997802734	0.0995117425918579
6.18499983102083	6104.3125	318.153991699219	0.0996785238385201
6.19510002434254	6066.21728515625	318.553985595703	0.100130848586559
6.20510010048747	6065.00341796875	318.954010009766	0.10052403062582
6.2151001766324	5947.14697265625	319.35400390625	0.101218856871128
6.22500013560057	6044.75048828125	319.753997802734	0.101347431540489
6.23519998043776	5914.00537109375	320.153991699219	0.102075681090355
6.24509993940592	6011.46142578125	320.553985595703	0.102206580340862
6.25499989837408	6091.7734375	320.954010009766	0.102384001016617
6.26520020887256	5978.861328125	321.35400390625	0.103063225746155
6.27500005066395	6073.548828125	321.753997802734	0.103200644254684
6.28500012680888	5954.2841796875	322.153991699219	0.103900633752346
6.29479996860027	6051.728515625	322.553985595703	0.104025706648827
6.30499981343746	5929.27880859375	322.954010009766	0.104738801717758
6.31489977240562	6028.25244140625	323.35400390625	0.104863598942757
6.32499996572733	6100.33837890625	323.753997802734	0.105064556002617
6.33519981056452	6001.57275390625	324.153991699219	0.105721779167652
6.3450001180172	6094.560546875	324.553985595703	0.105858683586121
6.35509984567761	5964.1220703125	324.954010009766	0.106582827866077
6.36499980464578	6061.193359375	325.35400390625	0.106694743037224
6.37499988079071	5934.08447265625	325.753997802734	0.10737881064415
6.38510007411242	6029.70556640625	326.153991699219	0.107516512274742
6.39500003308058	6113.52685546875	326.553985595703	0.107671305537224
6.40510022640228	5996.9384765625	326.954010009766	0.108350276947021
6.41490006819367	6088.40625	327.35400390625	0.108477808535099
6.42499979585409	5975.74462890625	327.753997802734	0.109153270721436
6.43490022048354	6073.87158203125	328.153991699219	0.10927277058363
6.44489983096719	5946.7216796875	328.553985595703	0.109984897077084
6.45500002428889	6047.390625	328.954010009766	0.110108688473701
6.46500010043383	5921.2060546875	329.35400390625	0.110812149941921
6.47500017657876	6018.40087890625	329.753997802734	0.110945776104927
6.48480001837015	6109.091796875	330.153991699219	0.111083805561066
6.49499986320734	5980.7802734375	330.553985595703	0.111806765198708
6.50499993935227	6079.3876953125	330.954010009766	0.111931651830673
6.51500001549721	6067.46044921875	331.35400390625	0.112367115914822
6.52510020881891	6068.32470703125	331.753997802734	0.112800121307373
6.53509981930256	6036.29541015625	332.153991699219	0.113300122320652
6.54509989544749	6046.55419921875	332.553985595703	0.113678254187107
6.5552000887692	5918.62548828125	332.954010009766	0.114447757601738
6.56510004773736	6011.4697265625	333.35400390625	0.114593654870987
6.57489988952875	6093.02099609375	333.753997802734	0.114757925271988
6.58489996567369	5969.7734375	334.153991699219	0.115503638982773
6.59490004181862	6068.607421875	334.553985595703	0.115633815526962
6.60490011796355	5939.31787109375	334.954010009766	0.116393387317657
6.61499984562397	6039.97119140625	335.35400390625	0.116524770855904
6.6249999217689	5922.3642578125	335.753997802734	0.117250323295593
6.63499999791384	6014.67578125	336.153991699219	0.117403976619244
6.64510019123554	6103.09765625	336.553985595703	0.117567971348763
6.6550001502037	5985.349609375	336.954010009766	0.11830485612154
6.66509987786412	6082.314453125	337.35400390625	0.11844028532505
6.67499983683228	5951.3701171875	337.753997802734	0.119202688336372
6.68489979580045	6049.4619140625	338.153991699219	0.11934107542038
6.69510010629892	6109.00146484375	338.553985595703	0.119580149650574
6.70500006526709	6008.72119140625	338.954010009766	0.120286084711552
6.7150997929275	6100.150390625	339.35400390625	0.120446741580963
6.72500021755695	5970.34619140625	339.753997802734	0.121228665113449
6.7349998280406	6069.2783203125	340.153991699219	0.121366456151009
6.74499990418553	5946.91796875	340.553985595703	0.122118048369884
6.75510009750724	6044.25537109375	340.954010009766	0.122261576354504
6.76510017365217	5945.94091796875	341.35400390625	0.122930005192757
6.77500013262033	6025.47216796875	341.753997802734	0.123117931187153
6.78500020876527	6080.408203125	342.153991699219	0.123343482613564
6.79480005055666	6038.21337890625	342.553985595703	0.123794265091419
6.80470000952482	5953.251953125	342.954010009766	0.124406404793262
6.81489985436201	6046.0634765625	343.35400390625	0.124554693698883
6.82500004768372	5933.11181640625	343.753997802734	0.12525050342083
6.83500012382865	6029.36865234375	344.153991699219	0.125381946563721
6.84500019997358	5893.8642578125	344.553985595703	0.126120075583458
6.855099927634	5994.265625	344.954010009766	0.126261159777641
6.86499988660216	6022.955078125	345.35400390625	0.126573145389557
6.8749999627471	5958.18798828125	345.753997802734	0.127124592661858
6.88500003889203	6047.07470703125	346.153991699219	0.127281308174133
6.89500011503696	5932.27197265625	346.553985595703	0.127966463565826
6.9050001911819	6028.900390625	346.954010009766	0.12809818983078
6.91499980166554	5910.041015625	347.35400390625	0.128773987293243
6.92499987781048	6007.40966796875	347.753997802734	0.128904193639755
6.93499995395541	5890.79248046875	348.153991699219	0.129590332508087
6.94489991292357	5987.15869140625	348.553985595703	0.129727333784103
6.95510022342205	5877.2763671875	348.954010009766	0.13039742410183
6.96500018239021	5971.19384765625	349.35400390625	0.130533590912819
6.97509991005063	5861.2177734375	349.753997802734	0.131201297044754
6.98509998619556	5956.35205078125	350.153991699219	0.131350040435791
6.9951000623405	5847.20751953125	350.553985595703	0.132020562887192
7.00510013848543	5944.46728515625	350.954010009766	0.132160842418671
7.01500009745359	5836.88427734375	351.35400390625	0.132826820015907
7.02530005946755	5936.32275390625	351.753997802734	0.132971093058586
7.03509990125895	5830.818359375	352.153991699219	0.133633106946945
7.04490020871162	5925.92236328125	352.553985595703	0.13376447558403
7.05489981919527	5825.2744140625	352.954010009766	0.134417682886124
7.0648998953402	5922.142578125	353.35400390625	0.134560436010361
7.07510020583868	5823.53759765625	353.753997802734	0.135211929678917
7.08509981632233	5918.876953125	354.153991699219	0.135357186198235
7.09509989246726	5825.65576171875	354.553985595703	0.135986149311066
7.10499985143542	5899.73681640625	354.954010009766	0.13617055118084
7.11510004475713	5825.2763671875	355.35400390625	0.136755913496017
7.12529988959432	5745.39697265625	355.753997802734	0.137367412447929
7.13529996573925	5834.365234375	356.153991699219	0.137526497244835
7.14549981057644	5747.90234375	356.553985595703	0.13813753426075
7.1553997695446	5840.9072265625	356.954010009766	0.138284161686897
7.16539984568954	5757.26318359375	357.35400390625	0.13888144493103
7.17510003596544	5697.10693359375	357.753997802734	0.139407813549042
7.18489987775683	5765.47998046875	358.153991699219	0.13960774242878
7.19500007107854	5683.171875	358.553985595703	0.140205845236778
7.2049000300467	5774.794921875	358.954010009766	0.14035302400589
7.21500022336841	5699	359.35400390625	0.140928640961647
7.22499983385205	5628.068359375	359.753997802734	0.141492575407028
7.23499990999699	5719.138671875	360.153991699219	0.141642823815346
7.24499998614192	5641.55908203125	360.553985595703	0.142220020294189
7.25500006228685	5576.5771484375	360.954010009766	0.142771750688553
7.26509978994727	5665.06982421875	361.35400390625	0.142932221293449
7.27509986609221	5593.98583984375	361.753997802734	0.143479228019714
7.28530017659068	5527.21875	362.153991699219	0.144039794802666
7.29529978707433	5618.18603515625	362.553985595703	0.144193455576897
7.30510009452701	5548.1630859375	362.954010009766	0.144739776849747
7.31500005349517	5483.064453125	363.35400390625	0.145281329751015
7.3250001296401	5559.07177734375	363.753997802734	0.145465061068535
7.33509985730052	5510.4716796875	364.153991699219	0.145962044596672
7.34520005062222	5444.16357421875	364.553985595703	0.146514639258385
7.35539989545941	5386.53662109375	364.954010009766	0.147045373916626
7.36539997160435	5476.6328125	365.35400390625	0.1471878439188
7.37510016188025	5414.53076171875	365.753997802734	0.147720977663994
7.38530000671744	5354.01416015625	366.153991699219	0.148256942629814
7.39519996568561	5299.44775390625	366.553985595703	0.148765400052071
7.40520004183054	5370.9208984375	366.954010009766	0.148969426751137
7.41529976949096	5331.30615234375	367.35400390625	0.149448230862617
7.42539996281266	5274.267578125	367.753997802734	0.149971082806587
7.43529992178082	5222.02490234375	368.153991699219	0.150475308299065
7.44529999792576	5167.84130859375	368.553985595703	0.150989443063736
7.45540019124746	5142.6513671875	368.954010009766	0.151439428329468
7.46539980173111	5201.03076171875	369.35400390625	0.151671454310417
7.47530022636056	5152.19873046875	369.753997802734	0.152165919542313
7.48529983684421	5100.48681640625	370.153991699219	0.152675867080688
7.49519979581237	5045.0546875	370.553985595703	0.153196975588799
7.50649999827147	2.18131995201111	370.954010009766	0.169743493199348
7.51660019159317	2.2588095664978	371.35400390625	0.170169323682785
7.52680003643036	2.34627747535706	371.753997802734	0.170572996139526
7.53659987822175	2.02924728393555	372.153991699219	0.170980021357536
7.54659995436668	2.7436511516571	372.553985595703	0.171387910842896
7.55660003051162	2.3684868812561	372.954010009766	0.171784907579422
7.56660010665655	2.44549369812012	373.35400390625	0.172193273901939
7.57660018280149	2.31082510948181	373.753997802734	0.172582820057869
7.5866999104619	2.68887758255005	374.153991699219	0.173000946640968
7.59669998660684	2.69929218292236	374.553985595703	0.173400685191154
7.606599945575	2.55766773223877	374.954010009766	0.1737961769104
7.61660002171993	2.08432793617249	375.35400390625	0.174207910895348
7.6264999806881	2.51409554481506	375.753997802734	0.174603775143623
7.63650005683303	2.5054612159729	376.153991699219	0.175007119774818
7.64650013297796	2.70911645889282	376.553985595703	0.175403654575348